<?xml version="1.0"?>

<robot xmlns:xacro="http://www.ros.org/wiki/xacro">
    <xacro:macro name="gh1_description" params="debug">
    <!-- Rotor related joint and link is only for demonstrate location. -->
    <!-- Actually, the rotor will rotate and the joint is not fixed. Reduction ratio should be
    considered. -->

    <material name="black">
      <color rgba="0.0 0.0 0.0 1.0" />
    </material>
    <material name="blue">
      <color rgba="0.0 0.0 0.8 1.0" />
    </material>
    <material name="green">
      <color rgba="0.0 0.8 0.0 1.0" />
    </material>
    <material name="grey">
      <color rgba="0.2 0.2 0.2 1.0" />
    </material>
    <material name="silver">
      <color rgba="0.913725490196 0.913725490196 0.847058823529 1.0" />
    </material>
    <material name="orange">
      <color rgba="0.12 0.15 0.2 1.0" />
    </material>
    <material name="brown">
      <color rgba="0.870588235294 0.811764705882 0.764705882353 1.0" />
    </material>
    <material name="red">
      <color rgba="0.8 0.0 0.0 1.0" />
    </material>
    <material name="white">
      <color rgba="1.0 1.0 1.0 1.0" />
    </material>

    <!-- Debug mode will hung up the robot, use "true" or "false" to switch it. -->
    <xacro:if value="${debug}">
      <link name="world" />
      <joint name="base_static_joint" type="fixed">
        <origin rpy="0 0 0" xyz="0 0 0.0" />
        <parent link="world" />
        <child link="base" />
      </joint>
    </xacro:if>

    <link name="base">
      <visual>
        <origin rpy="0 0 0" xyz="0 0 0" />
        <geometry>
          <box size="0.001 0.001 0.001" />
        </geometry>
      </visual>
    </link>

    <joint name="floating_base" type="fixed">
      <origin rpy="0 0 0" xyz="0 0 0" />
      <parent link="base" />
      <child link="body" />
    </joint>

    <link name="body">
      <inertial>
        <origin
          xyz="-0.0057915 -8.0007E-06 0.16"
          rpy="0 0 0" />
        <mass
          value="23.55" />
        <inertia
          ixx="0.46786000"
          ixy="0"
          ixz="0"
          iyy="0.37758500"
          iyz="0"
          izz="0.21744500" />
      </inertial>
      <visual>
        <origin
          xyz="0 0 0"
          rpy="0 0 0" />
        <geometry>
          <mesh
            filename="/home/wl/Documents/simulation_all_ros2/src/robot_description/gh1/meshes/base_link.STL" />
        </geometry>
        <material
          name="">
          <color
            rgba="1 1 1 0.3" />
        </material>
      </visual>
      <!-- trunk -->
      <collision>
        <origin
          xyz="0 0 0"
          rpy="0 0 0" />
        <geometry>
          <box size="0.18 0.28 0.4" />
        </geometry>
      </collision>
      <!-- upper right arm -->
      <collision>
        <origin
          xyz="0 -0.24 0"
          rpy="-0.15 0 0" />
        <geometry>
          <cylinder radius="0.01" length="0.28" />
        </geometry>
      </collision>
      <!-- upper left arm -->
      <collision>
        <origin
          xyz="0 0.24 0"
          rpy="0.15 0 0" />
        <geometry>
          <cylinder radius="0.01" length="0.28" />
        </geometry>
      </collision>
      <!-- lower right arm -->
      <collision>
        <origin
          xyz="0.06 -0.3 -0.3"
          rpy="-0.3 -0.45 0" />
        <geometry>
          <cylinder radius="0.01" length="0.28" />
        </geometry>
      </collision>
      <!-- lower left arm -->
      <collision>
        <origin
          xyz="0.06 0.3 -0.3"
          rpy="0.3 -0.45 0" />
        <geometry>
          <cylinder radius="0.01" length="0.28" />
        </geometry>
      </collision>
    </link>

    <joint name="z_joint_imu" type="fixed">
      <origin xyz="-0.0 0 -0.0" rpy="0 0 0" />
      <parent link="body" />
      <child link="imu_link" />
    </joint>

    <link name="imu_link">
      <visual>
        <origin xyz="-0.0 0 -0.0" rpy="0 0 0" />
        <geometry>
          <box size="0.05 0.05 0.02" />
        </geometry>
        <material name="">
          <color rgba="0.75294 0.75294 0.75294 1" />
        </material>
      </visual>
    </link>

    <joint
      name="l_hip_roll"
      type="revolute">
      <origin
        xyz="-0.08275 0.135 -0.2975"
        rpy="0 0 0" />
      <parent
        link="body" />
      <child
        link="l_thigh_roll" />
      <axis
        xyz="1 0 0" />
      <limit
        lower="-0.17"
        upper="1.05"
        effort="120"
        velocity="20.92" />
    </joint>

    <link
      name="l_thigh_roll">
      <inertial>
        <origin
          xyz="0.078159 0.0 0.003801"
          rpy="0 0 0" />
        <mass
          value="2.19" />
        <inertia
          ixx="0.00262800"
          ixy="0"
          ixz="0"
          iyy="0.00262800"
          iyz="0"
          izz="0.00394200" />
      </inertial>
      <visual>
        <origin
          xyz="0 0 0"
          rpy="0 0 0" />
        <geometry>
          <mesh
            filename="/home/wl/Documents/simulation_all_ros2/src/robot_description/gh1/meshes/L1_link.STL" />
        </geometry>
        <material
          name="">
          <color
            rgba="1 1 1 0.3" />
        </material>
      </visual>
      <collision>
        <origin
          xyz="0.085 0 0"
          rpy="0 0 0" />
        <geometry>
          <cylinder radius="0.06" length="0.06" />
        </geometry>
      </collision>
    </link>

    <joint
      name="l_hip_yaw"
      type="revolute">
      <origin
        xyz="0.087 0 -0.015"
        rpy="0 0 0" />
      <parent link="l_thigh_roll" />
      <child link="l_thigh_yaw" />
      <axis
        xyz="0 0 1" />
      <limit
        lower="-0.1"
        upper="0.1"
        effort="70"
        velocity="12.552" />
    </joint>

    <link
      name="l_thigh_yaw">
      <inertial>
        <origin
          xyz="-1.5406E-05 -0.039347 -0.093587"
          rpy="0 0 0" />
        <mass
          value="2.72" />
        <inertia
          ixx="0.00754800"
          ixy="0"
          ixz="0"
          iyy="0.00754800"
          iyz="0"
          izz="0.00489600" />
      </inertial>
      <visual>
        <origin
          xyz="0 0 0"
          rpy="0 0 0" />
        <geometry>
          <mesh
            filename="/home/wl/Documents/simulation_all_ros2/src/robot_description/gh1/meshes/L2_link.STL" />
        </geometry>
        <material
          name="">
          <color
            rgba="1 1 1 0.3" />
        </material>
      </visual>
      <collision>
        <origin
          xyz="0 -0.01 -0.13"
          rpy="-1.57 0 0" />
        <geometry>
          <cylinder radius="0.06" length="0.15" />
        </geometry>
      </collision>
    </link>

    <joint name="l_hip_pitch" type="revolute">
      <origin
        xyz="0 -0.041 -0.127"
        rpy="0 0 0" />
      <parent link="l_thigh_yaw" />
      <child link="l_thigh_pitch" />
      <axis
        xyz="0 1 0" />
      <limit
        lower="-1.75"
        upper="1.75"
        effort="120"
        velocity="20.92" />
    </joint>

    <link name="l_thigh_pitch">
      <inertial>
        <origin
          xyz="0.0075478 0.052643 -0.12044"
          rpy="0 0 0" />
        <mass
          value="4.07" />
        <inertia
          ixx="0.04239583"
          ixy="0"
          ixz="0"
          iyy="0.04320983"
          iyz="0"
          izz="0.00250983" />
      </inertial>
      <visual>
        <origin
          xyz="0 0 0"
          rpy="0 0 0" />
        <geometry>
          <mesh
            filename="/home/wl/Documents/simulation_all_ros2/src/robot_description/gh1/meshes/L3_link.STL" />
        </geometry>
        <material
          name="">
          <color
            rgba="1 1 1 0.3" />
        </material>
      </visual>
      <collision>
        <origin
          xyz="0.02 0.04 -0.25"
          rpy="0 0 0" />
        <geometry>
          <box size="0.07 0.05 0.35"/>
        </geometry>
      </collision>
    </link>

    <joint name="l_knee_pitch" type="revolute">
      <origin
        xyz="0 0.041 -0.42"
        rpy="0 0 0" />
      <parent link="l_thigh_pitch" />
      <child link="l_shank_pitch" />
      <axis
        xyz="0 1 0" />
      <limit
        lower="0"
        upper="2.23"
        effort="120"
        velocity="20.92" />
    </joint>

    <link name="l_shank_pitch">
      <inertial>
        <origin
          xyz="0.0023769 -0.0025816 -0.15422"
          rpy="0 0 0" />
        <mass
          value="1.88" />
        <inertia
          ixx="0.01617442"
          ixy="0"
          ixz="0"
          iyy="0.01660667"
          iyz="0"
          izz="0.00069576" />
      </inertial>
      <visual>
        <origin
          xyz="0 0 0"
          rpy="0 0 0" />
        <geometry>
          <mesh
            filename="/home/wl/Documents/simulation_all_ros2/src/robot_description/gh1/meshes/L4_link.STL" />
        </geometry>
        <material
          name="">
          <color
            rgba="1 1 1 0.3" />
        </material>
      </visual>
      <collision>
        <origin
          xyz="0 0 -0.22"
          rpy="0 0 0" />
        <geometry>
          <box size="0.06 0.029 0.32"/>
        </geometry>
      </collision>
    </link>

    <joint name="l_ankle_pitch" type="revolute">
      <origin
        xyz="0 0 -0.4"
        rpy="0 0 0" />
      <parent link="l_shank_pitch" />
      <child link="l_foot_pitch" />
      <axis
        xyz="0 1 0" />
      <limit
        lower="-1.08"
        upper="0.59"
        effort="22"
        velocity="46.024" />
    </joint>

    <link name="l_foot_pitch">
      <inertial>
        <origin
          xyz="0.022131 0.0001084 -0.040348"
          rpy="0 0 0" />
        <mass
          value="0.55" />
        <inertia
          ixx="0.00013292"
          ixy="0"
          ixz="0"
          iyy="0.00288292"
          iyz="0"
          izz="0.00297917" />
      </inertial>
      <visual>
        <origin
          xyz="0 0 0"
          rpy="0 0 0" />
        <geometry>
          <mesh
            filename="/home/wl/Documents/simulation_all_ros2/src/robot_description/gh1/meshes/L5_link.STL" />
        </geometry>
        <material
          name="">
          <color
            rgba="1 1 1 0.3" />
        </material>
      </visual>
      <!-- <collision>
        <origin
          xyz="0.025 0 -0.045"
          rpy="0 0 0" />
        <geometry>
          <box size="0.25 0.05 0.02"/>
        </geometry>
      </collision> -->
      <collision>
        <origin
          xyz="0.02 0 -0.04"
          rpy="0 1.57 0" />
        <geometry>
          <cylinder radius="0.015" length="0.22"/>
        </geometry>
      </collision>
      <collision>
        <origin
          xyz="0.13 0 -0.04"
          rpy="0 0 0" />
        <geometry>
          <sphere radius="0.015"/>
        </geometry>
      </collision>
      <collision>
        <origin
          xyz="-0.09 0 -0.04"
          rpy="0 0 0" />
        <geometry>
          <sphere radius="0.015"/>
        </geometry>
      </collision>
    </link>

    <link name="r_thigh_roll">
      <inertial>
        <origin
          xyz="0.078159 0.0 0.003801"
          rpy="0 0 0" />
        <mass
          value="2.19" />
        <inertia
          ixx="0.00262800"
          ixy="0"
          ixz="0"
          iyy="0.00262800"
          iyz="0"
          izz="0.00394200" />
      </inertial>
      <visual>
        <origin
          xyz="0 0 0"
          rpy="0 0 0" />
        <geometry>
          <mesh
            filename="/home/wl/Documents/simulation_all_ros2/src/robot_description/gh1/meshes/R1_link.STL" />
        </geometry>
        <material
          name="">
          <color
            rgba="1 1 1 0.3" />
        </material>
      </visual>
      <collision>
        <origin
          xyz="0.085 0 0"
          rpy="0 0 0" />
        <geometry>
          <cylinder radius="0.06" length="0.06" />
        </geometry>
      </collision>
    </link>

    <joint name="r_hip_roll" type="revolute">
      <origin
        xyz="-0.08275 -0.135 -0.2975"
        rpy="0 0 0" />
      <parent link="body" />
      <child link="r_thigh_roll" />
      <axis
        xyz="1 0 0" />
      <limit
        lower="-1.05"
        upper="0.17"
        effort="120"
        velocity="20.92" />
    </joint>

    <link
      name="r_thigh_yaw">
      <inertial>
        <origin
          xyz="-1.5311E-05 0.039347 -0.093587"
          rpy="0 0 0" />
        <mass
          value="2.72" />
        <inertia
          ixx="0.00754800"
          ixy="0"
          ixz="0"
          iyy="0.00754800"
          iyz="0"
          izz="0.00489600" />
      </inertial>
      <visual>
        <origin
          xyz="0 0 0"
          rpy="0 0 0" />
        <geometry>
          <mesh
            filename="/home/wl/Documents/simulation_all_ros2/src/robot_description/gh1/meshes/R2_link.STL" />
        </geometry>
        <material
          name="">
          <color
            rgba="1 1 1 0.3" />
        </material>
      </visual>
      <collision>
        <origin
          xyz="0 0.01 -0.13"
          rpy="1.57 0 0" />
        <geometry>
          <cylinder radius="0.06" length="0.15" />
        </geometry>
      </collision>
    </link>

    <joint name="r_hip_yaw" type="revolute">
      <origin
        xyz="0.087 0 -0.015"
        rpy="0 0 0" />
      <parent link="r_thigh_roll" />
      <child link="r_thigh_yaw" />
      <axis
        xyz="0 0 1" />
      <limit
        lower="-0.1"
        upper="0.1"
        effort="70"
        velocity="12.552" />
    </joint>

    <link
      name="r_thigh_pitch">
      <inertial>
        <origin
          xyz="0.0075476 -0.052643 -0.12045"
          rpy="0 0 0" />
        <mass
          value="4.07" />
        <inertia
          ixx="0.04239583"
          ixy="0"
          ixz="0"
          iyy="0.04320983"
          iyz="0"
          izz="0.00250983" />
      </inertial>
      <visual>
        <origin
          xyz="0 0 0"
          rpy="0 0 0" />
        <geometry>
          <mesh
            filename="/home/wl/Documents/simulation_all_ros2/src/robot_description/gh1/meshes/R3_link.STL" />
        </geometry>
        <material
          name="">
          <color
            rgba="1 1 1 0.3" />
        </material>
      </visual>
      <collision>
        <origin
          xyz="0.02 -0.04 -0.25"
          rpy="0 0 0" />
        <geometry>
          <box size="0.07 0.05 0.35"/>
        </geometry>
      </collision>
    </link>

    <joint name="r_hip_pitch" type="revolute">
      <origin
        xyz="0 0.041 -0.127"
        rpy="0 0 0" />
      <parent link="r_thigh_yaw" />
      <child link="r_thigh_pitch" />
      <axis
        xyz="0 1 0" />
      <limit
        lower="-1.75"
        upper="1.75"
        effort="120"
        velocity="20.92" />
    </joint>

    <link name="r_shank_pitch">
      <inertial>
        <origin
          xyz="0.0023769 0.0025816 -0.15422"
          rpy="0 0 0" />
        <mass
          value="1.88" />
        <inertia
          ixx="0.01617442"
          ixy="0"
          ixz="0"
          iyy="0.01660667"
          iyz="0"
          izz="0.00069576" />
      </inertial>
      <visual>
        <origin
          xyz="0 0 0"
          rpy="0 0 0" />
        <geometry>
          <mesh
            filename="/home/wl/Documents/simulation_all_ros2/src/robot_description/gh1/meshes/R4_link.STL" />
        </geometry>
        <material
          name="">
          <color
            rgba="1 1 1 0.3" />
        </material>
      </visual>
      <collision>
        <origin
          xyz="0 0 -0.22"
          rpy="0 0 0" />
        <geometry>
          <box size="0.06 0.029 0.32"/>
        </geometry>
      </collision>
    </link>

    <joint name="r_knee_pitch" type="revolute">
      <origin
        xyz="0 -0.041 -0.42"
        rpy="0 0 0" />
      <parent link="r_thigh_pitch" />
      <child link="r_shank_pitch" />
      <axis
        xyz="0 1 0" />
      <limit
        lower="0"
        upper="2.23"
        effort="120"
        velocity="20.92" />
    </joint>

    <link name="r_foot_pitch">
      <inertial>
        <origin
          xyz="0.022131 -0.0001084 -0.040348"
          rpy="0 0 0" />
        <mass
          value="0.55" />
        <inertia
          ixx="0.00013292"
          ixy="0"
          ixz="0"
          iyy="0.00288292"
          iyz="0"
          izz="0.00297917" />
      </inertial>
      <visual>
        <origin
          xyz="0 0 0"
          rpy="0 0 0" />
        <geometry>
          <mesh
            filename="/home/wl/Documents/simulation_all_ros2/src/robot_description/gh1/meshes/R5_link.STL" />
        </geometry>
        <material
          name="">
          <color
            rgba="1 1 1 0.3" />
        </material>
      </visual>
      <collision>
        <origin
          xyz="0.02 0 -0.04"
          rpy="0 1.57 0" />
        <geometry>
          <cylinder radius="0.015" length="0.22"/>
        </geometry>
      </collision>
      <collision>
        <origin
          xyz="0.13 0 -0.04"
          rpy="0 0 0" />
        <geometry>
          <sphere radius="0.015"/>
        </geometry>
      </collision>
      <collision>
        <origin
          xyz="-0.09 0 -0.04"
          rpy="0 0 0" />
        <geometry>
          <sphere radius="0.015"/>
        </geometry>
      </collision>
    </link>

    <joint name="r_ankle_pitch" type="revolute">
      <origin
        xyz="0 0 -0.4"
        rpy="0 0 0" />
      <parent link="r_shank_pitch" />
      <child link="r_foot_pitch" />
      <axis
        xyz="0 1 0" />
      <limit
        lower="-1.08"
        upper="0.59"
        effort="22"
        velocity="46.024" />
    </joint>

  </xacro:macro>
</robot>