<?xml version="1.0"?>

<robot name="mz_description" xmlns:xacro="http://www.ros.org/wiki/xacro">

    <xacro:include filename="$(find mz_description)/xacro/const.xacro"/>
    <xacro:include filename="$(find mz_description)/xacro/materials.xacro"/>
    <xacro:include filename="$(find mz_description)/xacro/leg.xacro"/>
    <xacro:include filename="$(find mz_description)/xacro/gazebo.xacro"/>
    <xacro:include filename="$(find mz_description)/xacro/transmission.xacro"/>

    <!-- Rotor related joint and link is only for demonstrate location. -->
    <!-- Actually, the rotor will rotate and the joint is not fixed. Reduction ratio should be considered. -->

    <!-- Debug mode will hung up the robot, use "true" or "false" to switch it. -->
    <xacro:if value="$(arg DEBUG)">
        <link name="world"/>
        <joint name="base_static_joint" type="fixed">
            <origin rpy="0 0 0" xyz="0 0 0"/>
            <parent link="world"/>
            <child link="base"/>
        </joint>
    </xacro:if> 

    <link name="base">
        <visual>
            <origin rpy="0 0 0" xyz="0 0 0"/>
            <geometry>
                <box size="0.001 0.001 0.001"/>
            </geometry>
        </visual>
    </link>

    <joint name="floating_base" type="fixed">
        <origin rpy="0 0 0" xyz="0 0 0"/>
        <parent link="base"/>
        <child link="trunk"/>
    </joint>

    <link name="trunk">
        <visual>
        <origin rpy="0 0 0" xyz="0 0 0"/>
        <geometry>
            <mesh filename="package://mz_description/meshes/trunk.dae" scale="1 1 1"/>
        </geometry>
        <material name="silver"/>
        </visual>
        <collision>
        <origin rpy="0 0 0" xyz="0 0 0.075"/>
        <geometry>
            <box size="0.470 0.3 0.150"/>
        </geometry>
        </collision>
        <inertial>
        <origin rpy="0 0 0" xyz="0.04 -0.02 -0.0003117"/>
        <mass value="16.6"/>
        <inertia ixx="0.124986" ixy="-2.879308e-04" ixz="0.001458170" iyy="0.491519" iyz="-6.43446e-04" izz="0.5473926"/>
        </inertial>
    </link>
    
    <joint name="FR_hip_joint" type="revolute">
        <origin rpy="0 0 0" xyz="0.22626 -0.070008 0.075"/>
        <parent link="trunk"/>
        <child link="FR_hip"/>
        <axis xyz="1 0 0"/>
        <dynamics damping="0" friction="0"/>
        <limit effort="60" lower="-1.04" upper="1.04" velocity="9"/>
    </joint>

    <link name="FR_hip">
        <visual>
        <origin xyz="0 0 0" rpy="0 0 0" />
        <geometry>
            <mesh filename="package://mz_description/meshes/FR_hip.dae" scale="1 1 1"/>
        </geometry>
        <material name="silver"/>
        </visual>
        <inertial>
        <origin rpy="0 0 0" xyz="0.083541 -0.0016537 1.2994E-05"/>
        <mass value="1.6"/>
        <inertia ixx="0.001582101" ixy="-0.0001151304" ixz="-4.046387E-06" iyy="0.002797035" iyz="0.000004285818" izz="0.001731282"/>
        </inertial>
    </link>

    <joint name="FR_hip_fixed" type="fixed">
        <origin rpy="0 0 0" xyz="0 -0.081 0"/>
        <parent link="FR_hip"/>
        <child link="FR_thigh_shoulder"/>
    </joint>
    <!-- this link is only for collision -->
    <link name="FR_thigh_shoulder">
        <!-- <collision>
        <origin rpy="1.57079632679 0 0" xyz="0 0 0"/>
        <geometry>
            <cylinder length="0.032" radius="0.041"/>
        </geometry>
        </collision> -->
    </link>

    <joint name="FR_thigh_joint" type="revolute">
        <origin rpy="0 0 0" xyz="0.08775 -0.02125 0"/>
        <parent link="FR_hip"/>
        <child link="FR_thigh"/>
        <axis xyz="0 1 0"/>
        <dynamics damping="0" friction="0"/>
        <limit effort="60" lower="-1.482" upper="3.9269" velocity="9"/>
    </joint>

    <link name="FR_thigh">
        <visual>
        <origin rpy="0 0 0" xyz="0 0 0"/>
        <geometry>
            <mesh filename="package://mz_description/meshes/thigh.dae" scale="1 1 1"/>
        </geometry>
        <material name="silver"/>
        </visual>
        <collision>
        <origin xyz="-0.022 -0.094 -0.115" rpy="0 0 0" />
        <geometry>
            <box size="0.04 0.025 0.30"/>
        </geometry>
        </collision>
        <inertial>
        <origin rpy="0 0 0" xyz="-0.0027386 -0.061044 -0.025431"/>
        <mass value="2.7"/>
        <inertia ixx="0.0370827" ixy="-0.0005225046" ixz="-0.002171109" iyy="0.03654717" iyz="-0.004972422" izz="0.004880799"/>
        </inertial>
    </link>

    <joint name="FR_calf_joint" type="revolute">
        <origin rpy="0 0 0" xyz="0 -0.09275 -0.3"/>
        <parent link="FR_thigh"/>
        <child link="FR_calf"/>
        <axis xyz="0 1 0"/>
        <dynamics damping="0" friction="0"/>
        <limit effort="60" lower="-2.8099" upper="-1.0297" velocity="9"/>
    </joint>

    <link name="FR_calf">
        <visual>
        <origin rpy="0 0 0" xyz="0 0 0"/>
        <geometry>
            <mesh filename="package://mz_description/meshes/calf.dae" scale="1 1 1"/>
        </geometry>
        <material name="silver"/>
        </visual>
        <collision>
        <origin xyz="0.018 0 -0.16" rpy="0 -0.10 0" />
        <geometry>
            <box size= "0.02 0.02 0.24"/>
        </geometry>
        </collision>
        <!-- <collision>
        <origin xyz="0.03 0 -0.245" rpy="0 0.35 0" />
        <geometry>
            "<box size= "0.02 0.02 0.06"/>
        </geometry>
        </collision> -->
        <inertial>
        <origin rpy="0 0 0" xyz="0.0079835 -6.7794E-06 -0.18022"/>
        <mass value="0.23"/>
        <inertia ixx="0.00650717" ixy="0.0" ixz="0.0003660643" iyy="0.006566385" iyz="0.0" izz="0.0001884405"/>
        </inertial>
    </link>

    <joint name="FR_foot_fixed" type="fixed" dont_collapse="true">
        <origin rpy="0 0 0" xyz="0 0 -0.302"/>
        <parent link="FR_calf"/>
        <child link="FR_foot"/>
    </joint>

    <link name="FR_foot">
        <visual>
        <origin rpy="0 0 0" xyz="0 0 0"/>
        <geometry>
            <sphere radius="0.01"/>
        </geometry>
        <material name="silver"/>
        </visual>
        <collision>
        <origin rpy="0 0 0" xyz="0 0 0"/>
        <geometry>
            <!-- <sphere radius="0.02"/> -->
            <sphere radius="0.0235"/>
        </geometry>
        </collision>
        <inertial>
        <mass value="0.07"/>
        <inertia ixx="0.00002111109" ixy="0.0" ixz="0.000006111105" iyy="0.000022777755" iyz="0.0" izz="0.00002333331"/>
        </inertial>
    </link>

    <joint name="FL_hip_joint" type="revolute">
        <origin rpy="0 0 0" xyz="0.22626 0.069992 0.075"/>
        <parent link="trunk"/>
        <child link="FL_hip"/>
        <axis xyz="1 0 0"/>
        <dynamics damping="0" friction="0"/>
        <limit effort="60" lower="-1.04" upper="1.04" velocity="9"/>
    </joint>

    <link name="FL_hip">
        <visual>
        <!-- the same as a1 -->
        <origin rpy="0 0 0" xyz="0 0 0"/>
        <geometry>
            <mesh filename="package://mz_description/meshes/FL_hip.dae" scale="1 1 1"/>
        </geometry>
        <material name="silver"/>
        </visual>
        <inertial>
        <origin rpy="0 0 0" xyz="0.083541 0.0016537 -1.2994E-05"/>
        <mass value="1.6"/>
        <inertia ixx="0.001986561" ixy="0.000042857612" ixz="-0.00000022566089" iyy="0.002917609" iyz="0.00000000239428" izz="0.002219916"/>
        </inertial>
    </link>

    <joint name="FL_hip_fixed" type="fixed">
        <origin rpy="0 0 0" xyz="0 0.081 0"/>
        <parent link="FL_hip"/>
        <child link="FL_thigh_shoulder"/>
    </joint>
    <!-- this link is only for collision -->
    <link name="FL_thigh_shoulder">
        <!-- <collision>
        <origin rpy="1.57079632679 0 0" xyz="0 0 0"/>
        <geometry>
            <cylinder length="0.032" radius="0.041"/>
        </geometry>
        </collision> -->
    </link>

    <joint name="FL_thigh_joint" type="revolute">
        <origin rpy="0 0 0" xyz="0.08775 0.02125 0"/>
        <parent link="FL_hip"/>
        <child link="FL_thigh"/>
        <axis xyz="0 1 0"/>
        <dynamics damping="0" friction="0"/>
        <limit effort="60" lower="-1.482" upper="3.9269" velocity="9"/>
    </joint>

    <link name="FL_thigh">
        <visual>
        <origin rpy="0 0 0" xyz="0 0 0"/>
        <geometry>
            <mesh filename="package://mz_description/meshes/thigh_mirror.dae" scale="1 1 1"/>
        </geometry>
        <material name="silver"/>
        </visual>
        <collision>
        <origin xyz="-0.022 0.094 -0.115" rpy="0 0 0" />
        <geometry>
            <box size="0.04 0.025 0.30"/>
        </geometry>
        </collision>
        <inertial>
        <origin rpy="0 0 0" xyz="-0.0027198 0.061044 -0.025411"/>
        <mass value="2.7"/>
        <inertia ixx="0.0370822" ixy="0.0005224988" ixz="-0.002171101" iyy="0.03654652" iyz="0.00497237" izz="0.004880707"/>
        </inertial>
    </link>

    <joint name="FL_calf_joint" type="revolute">
        <origin rpy="0 0 0" xyz="0 0.09275 -0.3"/>
        <parent link="FL_thigh"/>
        <child link="FL_calf"/>
        <axis xyz="0 1 0"/>
        <dynamics damping="0" friction="0"/>
        <limit effort="60" lower="-2.8099" upper="-1.0297" velocity="9"/>
    </joint>

    <link name="FL_calf">
        <visual>
        <origin rpy="0 0 0" xyz="0 0 0"/>
        <geometry>
            <mesh filename="package://mz_description/meshes/calf.dae" scale="1 1 1"/>
        </geometry>
        <material name="silver"/>
        </visual>
        <collision>
        <origin xyz="0.018 0 -0.16" rpy="0 -0.10 0" />
        <geometry>
            <box size= "0.02 0.02 0.24"/>
        </geometry>
        </collision>
        <!-- <collision>
        <origin xyz="0.03 0 -0.245" rpy="0 0.35 0" />
        <geometry>
            "<box size= "0.02 0.02 0.06"/>
        </geometry>
        </collision> -->
        <inertial>
        <origin rpy="0 0 0" xyz="0.0079835 -6.7598E-06 -0.18022"/>
        <mass value="0.23"/>
        <inertia ixx="0.006507178" ixy="0.0" ixz="0.0003660643" iyy="0.006566385" iyz="0.0" izz="0.0001884405"/>
        </inertial>
    </link>

    <joint name="FL_foot_fixed" type="fixed" dont_collapse="true">
        <origin rpy="0 0 0" xyz="0 0 -0.302"/>
        <parent link="FL_calf"/>
        <child link="FL_foot"/>
    </joint>

    <link name="FL_foot">
        <visual>
        <origin rpy="0 0 0" xyz="0 0 0"/>
        <geometry>
            <sphere radius="0.015"/>
        </geometry>
        <material name="silver"/>
        </visual>
        <collision>
        <origin rpy="0 0 0" xyz="0 0 0"/>
        <geometry>
            <sphere radius="0.0235"/>
        </geometry>
        </collision>
        <inertial>
        <mass value="0.07"/>
        <!-- the same as a1 -->
        <inertia ixx="2.1111e-05" ixy="0.0" ixz="0.000006111105" iyy="0.000022777755" iyz="0.0" izz="0.00002333331"/>
        </inertial>
    </link>


    <joint name="RR_hip_joint" type="revolute">
        <origin rpy="0 0 0" xyz="-0.22624 -0.070008 0.075"/>
        <parent link="trunk"/>
        <child link="RR_hip"/>
        <axis xyz="1 0 0"/>
        <dynamics damping="0" friction="0"/>
        <limit effort="60" lower="-1.04" upper="1.04" velocity="9"/>
    </joint>

    <link name="RR_hip">
        <visual>
        <origin rpy="0 0 0" xyz="0 0 0"/>
        <geometry>
            <mesh filename="package://mz_description/meshes/RR_hip.dae" scale="1 1 1"/>
        </geometry>
        <material name="silver"/>
        </visual>
        <inertial>
        <origin rpy="0 0 0" xyz="-0.083541 -0.0016537 -1.2994E-05"/>
        <mass value="1.6"/>
        <inertia ixx="0.001986561" ixy="0.00004285820" ixz="0.0000002256640" iyy="0.002917650" iyz="-0.000000002394313" izz="0.002219947"/>
        </inertial>
    </link>

    <joint name="RR_hip_fixed" type="fixed">
        <origin rpy="0 0 0" xyz="0 -0.081 0"/>
        <parent link="RR_hip"/>
        <child link="RR_thigh_shoulder"/>
    </joint>
    <!-- this link is only for collision -->
    <link name="RR_thigh_shoulder">
        <!-- <collision>
        <origin rpy="1.57079632679 0 0" xyz="0 0 0"/>
        <geometry>
            <cylinder length="0.032" radius="0.041"/>
        </geometry>
        </collision> -->
    </link>

    <joint name="RR_thigh_joint" type="revolute">
        <origin rpy="0 0 0" xyz="-0.08775 -0.02125 0"/>
        <parent link="RR_hip"/>
        <child link="RR_thigh"/>
        <axis xyz="0 1 0"/>
        <dynamics damping="0" friction="0"/>
        <limit effort="60" lower="-0.6981" upper="4.7123" velocity="9"/>
    </joint>

    <link name="RR_thigh">
        <visual>
        <origin rpy="0 0 0" xyz="0 0 0"/>
        <geometry>
            <mesh filename="package://mz_description/meshes/thigh.dae" scale="1 1 1"/>
        </geometry>
        <material name="silver"/>
        </visual>
        <collision>
        <origin xyz="-0.022 -0.094 -0.115" rpy="0 0 0" />
        <geometry>
            <box size="0.04 0.025 0.30"/>
        </geometry>
        </collision>
        <inertial>
        <origin rpy="0 0 0" xyz="-0.0027386 -0.061044 -0.025431"/>
        <mass value="2.7"/>
        <inertia ixx="0.0370827" ixy="-0.000522505" ixz="-0.002171130" iyy="0.03654701" iyz="-0.00497243" izz="0.00488077"/>
        </inertial>
    </link>

    <joint name="RR_calf_joint" type="revolute">
        <origin rpy="0 0 0" xyz="0 -0.09275 -0.3"/>
        <parent link="RR_thigh"/>
        <child link="RR_calf"/>
        <axis xyz="0 1 0"/>
        <dynamics damping="0" friction="0"/>
        <limit effort="60" lower="-2.8099" upper="-1.0297" velocity="9"/>
    </joint>

    <link name="RR_calf">
        <visual>
        <origin rpy="0 0 0" xyz="0 0 0"/>
        <geometry>
            <mesh filename="package://mz_description/meshes/calf.dae" scale="1 1 1"/>
        </geometry>
        <material name="silver"/>
        </visual>
        <collision>
        <origin xyz="0.018 0 -0.16" rpy="0 -0.10 0" />
        <geometry>
            <box size= "0.02 0.02 0.24"/>
        </geometry>
        </collision>
        <!-- <collision>
        <origin xyz="0.03 0 -0.245" rpy="0 0.35 0" />
        <geometry>
            "<box size= "0.02 0.02 0.06"/>
        </geometry>
        </collision> -->
        <inertial>
        <origin rpy="0 0 0" xyz="0.0079835 -6.7795E-06 -0.18022"/>
        <mass value="0.23"/>
        <inertia ixx="0.00650709" ixy="0.0" ixz="0.0003660599" iyy="0.006566306" iyz="0.0" izz="0.0001884383"/>
        <!-- <inertia ixx="0.0034783165033113" ixy="0.0" ixz="-2.095735099337748e-4" iyy="0.0035020471523179" iyz="0.0" izz="4.622113907284768e-5" /> -->
        </inertial>
    </link>

    <joint name="RR_foot_fixed" type="fixed" dont_collapse="true">
        <origin rpy="0 0 0" xyz="0 0 -0.302"/>
        <parent link="RR_calf"/>
        <child link="RR_foot"/>
    </joint>
    <link name="RR_foot">
        <visual>
        <origin rpy="0 0 0" xyz="0 0 0"/>
        <geometry>
            <sphere radius="0.01"/>
        </geometry>
        <material name="silver"/>
        </visual>
        <collision>
        <origin rpy="0 0 0" xyz="0 0 0"/>
        <geometry>
            <sphere radius="0.0235"/>
        </geometry>
        </collision>
        <inertial>
        <mass value="0.07"/>
        <!-- the same as a1 -->
        <inertia ixx="2.11111e-05" ixy="0.0" ixz="0.000006111105" iyy="0.00002277775" iyz="0.0" izz="0.00002333331"/>
        </inertial>
    </link>


    <joint name="RL_hip_joint" type="revolute">
        <origin rpy="0 0 0" xyz="-0.22624 0.069992 0.075"/>
        <parent link="trunk"/>
        <child link="RL_hip"/>
        <axis xyz="1 0 0"/>
        <dynamics damping="0" friction="0"/>
        <limit effort="60" lower="-1.04" upper="1.04" velocity="9"/>
    </joint>

    <link name="RL_hip">
        <visual>
        <origin xyz="0 0 0" rpy="0 0 0" />
        <geometry>
            <mesh filename="package://mz_description/meshes/RL_hip.dae" scale="1 1 1"/>
        </geometry>
        <material name="silver"/>
        </visual>
        <inertial>
        <origin rpy="0 0 0" xyz="0.0037743 0.0038894 7.8535E-05"/>
        <mass value="1.6"/>
        <inertia ixx="0.001582101" ixy="-0.0001151304" ixz="0.000004046387" iyy="0.00279703" iyz="-0.000004285818" izz="0.002047615"/>
        </inertial>
    </link>

    <joint name="RL_hip_fixed" type="fixed">
        <origin rpy="0 0 0" xyz="0 0.081 0"/>
        <parent link="RL_hip"/>
        <child link="RL_thigh_shoulder"/>
    </joint>
    <!-- this link is only for collision -->
    <link name="RL_thigh_shoulder">
        <!-- <collision>
        <origin rpy="1.57079632679 0 0" xyz="0 0 0"/>
        <geometry>
            <cylinder length="0.032" radius="0.041"/>
        </geometry>
        </collision> -->
    </link>

    <joint name="RL_thigh_joint" type="revolute">
        <origin rpy="0 0 0" xyz="-0.08775 0.02125 0"/>
        <parent link="RL_hip"/>
        <child link="RL_thigh"/>
        <axis xyz="0 1 0"/>
        <dynamics damping="0" friction="0"/>
        <limit effort="60" lower="-0.6981" upper="4.7123" velocity="9"/>
    </joint>

    <link name="RL_thigh">
        <visual>
        <origin rpy="0 0 0" xyz="0 0 0"/>
        <geometry>
            <mesh filename="package://mz_description/meshes/thigh_mirror.dae" scale="1 1 1"/>
        </geometry>
        <material name="silver"/>
        </visual>
        <collision>
        <origin xyz="-0.022 0.094 -0.115" rpy="0 0 0" />
        <geometry>
            <box size="0.04 0.025 0.30"/>
        </geometry>
        </collision>
        <inertial>
        <origin rpy="0 0 0" xyz="-0.0027198 0.061044 -0.025411"/>
        <mass value="2.7"/>
        <inertia ixx="0.0370827" ixy="0.000522504" ixz="-0.002171109" iyy="0.0365471" iyz="0.00497242" izz="0.004880799"/>
        </inertial>
    </link>

    <joint name="RL_calf_joint" type="revolute">
        <origin rpy="0 0 0" xyz="0 0.09275 -0.3"/>
        <parent link="RL_thigh"/>
        <child link="RL_calf"/>
        <axis xyz="0 1 0"/>
        <dynamics damping="0" friction="0"/>
        <limit effort="60" lower="-2.8099" upper="-1.0297" velocity="9"/>
    </joint>

    <link name="RL_calf">
        <visual>
        <origin rpy="0 0 0" xyz="0 0 0"/>
        <geometry>
            <mesh filename="package://mz_description/meshes/calf.dae" scale="1 1 1"/>
        </geometry>
        <material name="silver"/>
        </visual>
        <collision>
        <origin xyz="0.018 0 -0.16" rpy="0 -0.10 0" />
        <geometry>
            <box size= "0.02 0.02 0.24"/>
        </geometry>
        </collision>
        <!-- <collision>
        <origin xyz="0.03 0 -0.245" rpy="0 0.35 0" />
        <geometry>
            "<box size= "0.02 0.02 0.06"/>
        </geometry>
        </collision> -->
        <inertial>
        <origin rpy="0 0 0" xyz="0.0079835 -6.7801E-06 -0.18022"/>
        <mass value="0.23"/>
        <inertia ixx="0.006507167" ixy="0.0" ixz="0.0003660637" iyy="0.006566375" iyz="0.0" izz="0.0001884402"/>
        <!-- <inertia ixx="0.0034783165033113" ixy="0.0" ixz="-1.614571428571429e-4" iyy="0.0026824344538288" iyz="0.0" izz="3.540362837837838e-5" /> -->
        </inertial>
    </link>

    <joint name="RL_foot_fixed" type="fixed" dont_collapse="true">
        <origin rpy="0 0 0" xyz="0 0 -0.302"/>
        <parent link="RL_calf"/>
        <child link="RL_foot"/>
    </joint>
    <link name="RL_foot">
        <visual>
        <origin rpy="0 0 0" xyz="0 0 0"/>
        <geometry>
            <sphere radius="0.01"/>
        </geometry>
        <material name="silver"/>
        </visual>
        <collision>
        <origin rpy="0 0 0" xyz="0 0 0"/>
        <geometry>
            <sphere radius="0.0235"/>
        </geometry>
        </collision>
        <inertial>
        <mass value="0.07"/>
        <!-- the same as a1 -->
        <inertia ixx="0.00002111109" ixy="0.0" ixz="0.000006111105" iyy="0.00002277775" iyz="0.0" izz="0.00002333331"/>
        </inertial>
    </link>
    
    <joint name="imu_joint" type="fixed">
        <parent link="trunk"/>
        <child link="imu_link"/>
        <origin rpy="0 0 0" xyz="0 0 0"/>
    </joint>

    <link name="imu_link">
        <inertial>
            <mass value="0.001"/>
            <origin rpy="0 0 0" xyz="0 0 0"/>
            <inertia ixx="0.0001" ixy="0" ixz="0" iyy="0.0001" iyz="0" izz="0.0001"/>
        </inertial>
        <visual>
            <origin rpy="0 0 0" xyz="0 0 0"/>
            <geometry>
                <box size="0.001 0.001 0.001"/>
            </geometry>
            <!-- <material name="red"/> -->
        </visual>
        <collision>
            <origin rpy="0 0 0" xyz="0 0 0"/>
            <geometry>
                <box size=".001 .001 .001"/>
            </geometry>
        </collision>
    </link>

    <xacro:leg_transmission name="FR"/>
    <xacro:leg_transmission name="FL"/>
    <xacro:leg_transmission name="RR"/>
    <xacro:leg_transmission name="RL"/>
    <!-- <xacro:stairs stairs="15" xpos="0" ypos="2.0" zpos="0" /> -->

</robot>
