<?xml version="1.0" encoding="utf-8"?>
<!-- This URDF was automatically created by SolidWorks to URDF Exporter! Originally created by
Stephen Brawner (brawner@gmail.com) 
     Commit Version: 1.5.1-0-g916b5db  Build Version: 1.5.7152.31018
     For more information, please see http://wiki.ros.org/sw_urdf_exporter -->
<robot name="iris3">

  <link name="world" />
  <joint name="world_fixed" type="fixed">
    <parent link="world" />
    <child link="base_link" />
  </joint>
  <link name="base_link">
    <inertial>
      <origin xyz="0.0028516 -9.0195E-06 0.074637" rpy="0 0 0" />
      <mass value="7.8345" />
      <inertia ixx="0.018345" ixy="7.5667E-06" ixz="0.00076837" iyy="0.016895" iyz="-5.4969E-06" izz="0.018588" />
    </inertial>
    <visual>
      <origin xyz="0 0 0" rpy="0 0 0" />
      <geometry>
        <mesh filename="package://iris_description/meshes/base_link.STL" />
      </geometry>
      <material name="">
        <color rgba="0.75294 0.75294 0.75294 1" />
      </material>
    </visual>
    <collision>
      <origin xyz="0 0 0" rpy="0 0 0" />
      <geometry>
        <mesh filename="package://iris_description/meshes/base_link.STL" />
      </geometry>
    </collision>
  </link>
  <joint name="Joint1" type="revolute">
    <origin xyz="0 0 0.1483" rpy="0 0 0" />
    <parent link="base_link" />
    <child link="Link1" />
    <axis xyz="0 0 1" />
    <limit lower="-3.14" upper="3.14" effort="50" velocity="5" />
  </joint>
  <link name="Link1">
    <inertial>
      <origin xyz="-1.168E-05 -0.028407 0.06315" rpy="0 0 0" />
      <mass value="5.8911" />
      <inertia ixx="0.0085269" ixy="1.3438E-06" ixz="-2.5107E-06" iyy="0.00801" iyz="0.00077853" izz="0.0084169" />
    </inertial>
    <visual>
      <origin xyz="0 0 0" rpy="0 0 0" />
      <geometry>
        <mesh filename="package://iris_description/meshes/Link1.STL" />
      </geometry>
      <material name="">
        <color rgba="0.75294 0.75294 0.75294 1" />
      </material>
    </visual>
    <collision>
      <origin xyz="0 0 0" rpy="0 0 0" />
      <geometry>
        <mesh filename="package://iris_description/meshes/Link1.STL" />
      </geometry>
    </collision>
  </link>
  <joint name="Joint2" type="revolute">
    <origin xyz="0 -0.0843 0.0697" rpy="1.5708 0 0" />
    <parent link="Link1" />
    <child link="Link2" />
    <axis xyz="0 0 1" />
    <limit lower="-3.14" upper="3.14" effort="50" velocity="5" />
  </joint>
  <link name="Link2">
    <inertial>
      <origin xyz="3.3206E-05 0.13 0.011523" rpy="0 0 0" />
      <mass value="3.2726" />
      <inertia ixx="0.035921" ixy="-5.4756E-07" ixz="-2.6668E-07" iyy="0.0027285" iyz="-2.3948E-09" izz="0.038096" />
    </inertial>
    <visual>
      <origin xyz="0 0 0" rpy="0 0 0" />
      <geometry>
        <mesh filename="package://iris_description/meshes/Link2.STL" />
      </geometry>
      <material name="">
        <color rgba="0.75294 0.75294 0.75294 1" />
      </material>
    </visual>
    <collision>
      <origin xyz="0 0 0" rpy="0 0 0" />
      <geometry>
        <mesh filename="package://iris_description/meshes/Link2.STL" />
      </geometry>
    </collision>
  </link>
  <joint name="Joint3" type="revolute">
    <origin xyz="0 0.26 0" rpy="0 0 0" />
    <parent link="Link2" />
    <child link="Link3" />
    <axis xyz="0 0 -1" />
    <limit lower="-3.14" upper="3.14" effort="50" velocity="5" />
  </joint>
  <link name="Link3">
    <inertial>
      <origin xyz="2.8791E-05 0.0054256 -0.054415" rpy="0 0 0" />
      <mass value="5.7323" />
      <inertia ixx="0.0079383" ixy="-3.0896E-06" ixz="4.6168E-06" iyy="0.0075193" iyz="0.00064614" izz="0.0075409" />
    </inertial>
    <visual>
      <origin xyz="0 0 0" rpy="0 0 0" />
      <geometry>
        <mesh filename="package://iris_description/meshes/Link3.STL" />
      </geometry>
      <material name="">
        <color rgba="0.75294 0.75294 0.75294 1" />
      </material>
    </visual>
    <collision>
      <origin xyz="0 0 0" rpy="0 0 0" />
      <geometry>
        <mesh filename="package://iris_description/meshes/Link3.STL" />
      </geometry>
    </collision>
  </link>
  <joint name="Joint4" type="revolute">
    <origin xyz="0 0.0747 -0.0843" rpy="1.5708 3.14 0" />
    <parent link="Link3" />
    <child link="Link4" />
    <axis xyz="0 0 -1" />
    <limit lower="-3.14" upper="3.14" effort="50" velocity="5" />
  </joint>
  <link name="Link4">
    <inertial>
      <origin xyz="-1.9758E-05 0.018994 -0.11496" rpy="0 0 0" />
      <mass value="5.6587" />
      <inertia ixx="0.012181" ixy="-5.5076E-08" ixz="-6.5469E-07" iyy="0.011681" iyz="0.0021098" izz="0.0053873" />
    </inertial>
    <visual>
      <origin xyz="0 0 0" rpy="0 0 0" />
      <geometry>
        <mesh filename="package://iris_description/meshes/Link4.STL" />
      </geometry>
      <material name="">
        <color rgba="0.75294 0.75294 0.75294 1" />
      </material>
    </visual>
    <collision>
      <origin xyz="0 0 0" rpy="0 0 0" />
      <geometry>
        <mesh filename="package://iris_description/meshes/Link4.STL" />
      </geometry>
    </collision>
  </link>
  <joint name="Joint5" type="revolute">
    <origin xyz="0 0.0843 -0.1843" rpy="-1.5708 0 0" />
    <parent link="Link4" />
    <child link="Link5" />
    <axis xyz="0 0 -1" />
    <limit lower="-3.14" upper="3.14" effort="50" velocity="5" />
  </joint>
  <link name="Link5">
    <inertial>
      <origin xyz="-3.644E-05 0.095994 -0.063695" rpy="0 0 0" />
      <mass value="3.7446" />
      <inertia ixx="0.008619" ixy="1.5506E-06" ixz="-3.1559E-06" iyy="0.0053531" iyz="0.002528" izz="0.0068338" />
    </inertial>
    <visual>
      <origin xyz="0 0 0" rpy="0 0 0" />
      <geometry>
        <mesh filename="package://iris_description/meshes/Link5.STL" />
      </geometry>
      <material name="">
        <color rgba="0.75294 0.75294 0.75294 1" />
      </material>
    </visual>
    <collision>
      <origin xyz="0 0 0" rpy="0 0 0" />
      <geometry>
        <mesh filename="package://iris_description/meshes/Link5.STL" />
      </geometry>
    </collision>
  </link>
  <joint name="Joint6" type="revolute">
    <origin xyz="0 0.1653 -0.0853" rpy="-1.5708 0 0" />
    <parent link="Link5" />
    <child link="Link6" />
    <axis xyz="0 0 -1" />
    <limit lower="-3.14" upper="3.14" effort="50" velocity="5" />
  </joint>
  <link name="Link6">
    <inertial>
      <origin xyz="0.00060533 -0.00072807 0.02091" rpy="0 0 0" />
      <mass value="1.0032" />
      <inertia ixx="0.00059254" ixy="-1.4767E-05" ixz="3.4108E-06" iyy="0.00059408" iyz="-3.762E-06" izz="0.00094124" />
    </inertial>
    <visual>
      <origin xyz="0 0 0" rpy="0 0 0" />
      <geometry>
        <mesh filename="package://iris_description/meshes/Link6.STL" />
      </geometry>
      <material name="">
        <color rgba="0.75294 0.75294 0.75294 1" />
      </material>
    </visual>
    <collision>
      <origin xyz="0 0 0" rpy="0 0 0" />
      <geometry>
        <mesh filename="package://iris_description/meshes/Link6.STL" />
      </geometry>
    </collision>
  </link>
  <transmission name="trans_Joint1">
    <type>transmission_interface/SimpleTransmission</type>
    <joint name="Joint1">
      <hardwareInterface>hardware_interface/PositionJointInterface</hardwareInterface>
    </joint>
    <actuator name="Joint1_motor">
      <hardwareInterface>hardware_interface/PositionJointInterface</hardwareInterface>
      <mechanicalReduction>1</mechanicalReduction>
    </actuator>
  </transmission>
  <transmission name="trans_Joint2">
    <type>transmission_interface/SimpleTransmission</type>
    <joint name="Joint2">
      <hardwareInterface>hardware_interface/PositionJointInterface</hardwareInterface>
    </joint>
    <actuator name="Joint2_motor">
      <hardwareInterface>hardware_interface/PositionJointInterface</hardwareInterface>
      <mechanicalReduction>1</mechanicalReduction>
    </actuator>
  </transmission>
  <transmission name="trans_Joint3">
    <type>transmission_interface/SimpleTransmission</type>
    <joint name="Joint3">
      <hardwareInterface>hardware_interface/PositionJointInterface</hardwareInterface>
    </joint>
    <actuator name="Joint3_motor">
      <hardwareInterface>hardware_interface/PositionJointInterface</hardwareInterface>
      <mechanicalReduction>1</mechanicalReduction>
    </actuator>
  </transmission>
  <transmission name="trans_Joint4">
    <type>transmission_interface/SimpleTransmission</type>
    <joint name="Joint4">
      <hardwareInterface>hardware_interface/PositionJointInterface</hardwareInterface>
    </joint>
    <actuator name="Joint4_motor">
      <hardwareInterface>hardware_interface/PositionJointInterface</hardwareInterface>
      <mechanicalReduction>1</mechanicalReduction>
    </actuator>
  </transmission>
  <transmission name="trans_Joint5">
    <type>transmission_interface/SimpleTransmission</type>
    <joint name="Joint5">
      <hardwareInterface>hardware_interface/PositionJointInterface</hardwareInterface>
    </joint>
    <actuator name="Joint5_motor">
      <hardwareInterface>hardware_interface/PositionJointInterface</hardwareInterface>
      <mechanicalReduction>1</mechanicalReduction>
    </actuator>
  </transmission>
  <transmission name="trans_Joint6">
    <type>transmission_interface/SimpleTransmission</type>
    <joint name="Joint6">
      <hardwareInterface>hardware_interface/PositionJointInterface</hardwareInterface>
    </joint>
    <actuator name="Joint6_motor">
      <hardwareInterface>hardware_interface/PositionJointInterface</hardwareInterface>
      <mechanicalReduction>1</mechanicalReduction>
    </actuator>
  </transmission>
  <gazebo>
    <plugin name="gazebo_ros_control" filename="libgazebo_ros_control.so">
      <robotNamespace>/</robotNamespace>
    </plugin>
  </gazebo>
</robot>