<?xml version="1.0" encoding="utf-8"?>
<!-- This URDF was automatically created by SolidWorks to URDF Exporter! Originally created by Stephen Brawner (brawner@gmail.com) 
     Commit Version: 1.5.1-0-g916b5db  Build Version: 1.5.7152.31018
     For more information, please see http://wiki.ros.org/sw_urdf_exporter -->
<robot name="mz04">
  <link name="trunk">
    <inertial>
      <origin xyz="0.022844 -0.012457 -0.00012974" rpy="0 0 0" />
      <mass value="4.9532" />
      <inertia ixx="0.016899" ixy="1.3713E-05" ixz="1.4164E-06" iyy="0.037802" iyz="0.00014959" izz="0.042043" />
    </inertial>
    <visual>
      <origin xyz="0 0 0" rpy="0 0 0" />
      <geometry>
        <mesh filename="package://mz04/meshes/trunk.dae" />
      </geometry>
      <material name="">
        <color rgba="1 1 1 1" />
      </material>
    </visual>
    <collision>
      <origin xyz="0 0 0" rpy="0 0 0" />
      <geometry>
        <!-- <mesh filename="package://mz04/meshes/trunk.dae" /> -->
      </geometry>
    </collision>
  </link>
  <link name="FR_hip">
    <inertial>
      <origin xyz="0.083541 -0.0016537 1.2994E-05" rpy="0 0 0" />
      <mass value="0.56406" />
      <inertia ixx="0.00061418" ixy="-3.2659E-06" ixz="8.3078E-08" iyy="0.0011773" iyz="-7.6935E-08" izz="0.00077313" />
    </inertial>
    <visual>
      <origin xyz="0 0 0" rpy="0 0 0" />
      <geometry>
        <mesh filename="package://mz04/meshes/FR_hip.dae" />
      </geometry>
      <material name="">
        <color rgba="1 1 1 1" />
      </material>
    </visual>
    <collision>
      <origin xyz="0 0 0" rpy="0 0 0" />
      <geometry>
        <!-- <mesh filename="package://mz04/meshes/FR_hip.dae" /> -->
      </geometry>
    </collision>
  </link>
  <joint name="FR_hip_joint" type="revolute">
    <origin xyz="0.22625 -0.07 0" rpy="0 0 0" />
    <parent link="trunk" />
    <child link="FR_hip" />
    <axis xyz="-1 0 0" />
    <limit lower="-3.14" upper="3.14" effort="50" velocity="20" />
  </joint>
  <link name="FR_thigh">
    <inertial>
      <origin xyz="-0.00078925 -0.061044 -0.025566" rpy="0 0 0" />
      <mass value="0.72376" />
      <inertia ixx="0.0046259" ixy="-1.8596E-05" ixz="-1.1948E-05" iyy="0.0048648" iyz="-0.00058927" izz="0.001047" />
    </inertial>
    <visual>
      <origin xyz="0 0 0" rpy="0 0 0" />
      <geometry>
        <mesh filename="package://mz04/meshes/thigh.dae" />
      </geometry>
      <material name="">
        <color rgba="1 1 1 1" />
      </material>
    </visual>
    <collision>
      <origin xyz="0 0 0" rpy="0 0 0" />
      <geometry>
        <!-- <mesh filename="package://mz04/meshes/FR_thigh.dae" /> -->
      </geometry>
    </collision>
  </link>
  <joint name="FR_thigh_joint" type="revolute">
    <origin xyz="0.08775 -0.02125 0" rpy="0 0 0" />
    <parent link="FR_hip" />
    <child link="FR_thigh" />
    <axis xyz="0 1 0" />
    <limit lower="-3.14" upper="3.14" effort="50" velocity="20" />
  </joint>
  <link name="FR_calf">
    <inertial>
      <origin xyz="-0.037767 -4.7349E-06 -0.17641" rpy="0 0 0" />
      <mass value="0.1253" />
      <inertia ixx="0.00096664" ixy="-1.5873E-08" ixz="-0.00015606" iyy="0.0010073" iyz="-1.3304E-08" izz="5.7049E-05" />
    </inertial>
    <visual>
      <origin xyz="0 0 0" rpy="0 0 0" />
      <geometry>
        <mesh filename="package://mz04/meshes/calf.dae" />
      </geometry>
      <material name="">
        <color rgba="1 1 1 1" />
      </material>
    </visual>
    <collision>
      <origin xyz="0 0 0" rpy="0 0 0" />
      <geometry>
        <!-- <mesh filename="package://mz04/meshes/FR_calf.dae" /> -->
      </geometry>
    </collision>
  </link>
  <joint name="FR_calf_joint" type="revolute">
    <origin xyz="0.022901 -0.09275 -0.29912" rpy="0 0 0" />
    <parent link="FR_thigh" />
    <child link="FR_calf" />
    <axis xyz="0 -1 0" />
    <limit lower="-3.14" upper="3.14" effort="50" velocity="20" />
  </joint>
  <link name="FL_hip">
    <inertial>
      <origin xyz="0.083541 0.0016537 -1.2994E-05" rpy="0 0 0" />
      <mass value="0.56406" />
      <inertia ixx="0.00061418" ixy="3.2659E-06" ixz="-8.3078E-08" iyy="0.0011773" iyz="-7.6935E-08" izz="0.00077313" />
    </inertial>
    <visual>
      <origin xyz="0 0 0" rpy="0 0 0" />
      <geometry>
        <mesh filename="package://mz04/meshes/FL_hip.dae" />
      </geometry>
      <material name="">
        <color rgba="1 1 1 1" />
      </material>
    </visual>
    <collision>
      <origin xyz="0 0 0" rpy="0 0 0" />
      <geometry>
        <!-- <mesh filename="package://mz04/meshes/FL_hip.dae" /> -->
      </geometry>
    </collision>
  </link>
  <joint name="FL_hip_joint" type="revolute">
    <origin xyz="0.22625 0.07 0" rpy="0 0 0" />
    <parent link="trunk" />
    <child link="FL_hip" />
    <axis xyz="-1 0 0" />
    <limit lower="-3.14" upper="3.14" effort="50" velocity="20" />
  </joint>
  <link name="FL_thigh">
    <inertial>
      <origin xyz="-0.00071416 0.061044 -0.025546" rpy="0 0 0" />
      <mass value="0.72376" />
      <inertia ixx="0.0046269" ixy="1.7521E-05" ixz="-4.0489E-06" iyy="0.0048657" iyz="0.00058962" izz="0.0010467" />
    </inertial>
    <visual>
      <origin xyz="0 0 0" rpy="0 0 0" />
      <geometry>
        <mesh filename="package://mz04/meshes/thigh_mirror.dae" />
      </geometry>
      <material name="">
        <color rgba="1 1 1 1" />
      </material>
    </visual>
    <collision>
      <origin xyz="0 0 0" rpy="0 0 0" />
      <geometry>
        <!-- <mesh filename="package://mz04/meshes/FL_thigh.dae" /> -->
      </geometry>
    </collision>
  </link>
  <joint name="FL_thigh_joint" type="revolute">
    <origin xyz="0.08775 0.02125 0" rpy="0 0 0" />
    <parent link="FL_hip" />
    <child link="FL_thigh" />
    <axis xyz="0 -1 0" />
    <limit lower="-3.14" upper="3.14" effort="50" velocity="20" />
  </joint>
  <link name="FL_calf">
    <inertial>
      <origin xyz="-0.037767 -4.7349E-06 -0.17641" rpy="0 0 0" />
      <mass value="0.1253" />
      <inertia ixx="0.00096664" ixy="-1.5873E-08" ixz="-0.00015606" iyy="0.0010073" iyz="-1.3304E-08" izz="5.7049E-05" />
    </inertial>
    <visual>
      <origin xyz="0 0 0" rpy="0 0 0" />
      <geometry>
        <mesh filename="package://mz04/meshes/calf.dae" />
      </geometry>
      <material name="">
        <color rgba="1 1 1 1" />
      </material>
    </visual>
    <collision>
      <origin xyz="0 0 0" rpy="0 0 0" />
      <geometry>
        <!-- <mesh filename="package://mz04/meshes/FL_calf.dae" /> -->
      </geometry>
    </collision>
  </link>
  <joint name="FL_calf_joint" type="revolute">
    <origin xyz="0.023579 0.09275 -0.29907" rpy="0 0 0" />
    <parent link="FL_thigh" />
    <child link="FL_calf" />
    <axis xyz="0 -1 0" />
    <limit lower="-3.14" upper="3.14" effort="50" velocity="20" />
  </joint>
  <link name="RR_hip">
    <inertial>
      <origin xyz="-0.083541 -0.0016537 -1.2994E-05" rpy="0 0 0" />
      <mass value="0.56406" />
      <inertia ixx="0.00061418" ixy="3.2659E-06" ixz="8.3078E-08" iyy="0.0011773" iyz="7.6935E-08" izz="0.00077313" />
    </inertial>
    <visual>
      <origin xyz="0 0 0" rpy="0 0 0" />
      <geometry>
        <mesh filename="package://mz04/meshes/RR_hip.dae" />
      </geometry>
      <material name="">
        <color rgba="1 1 1 1" />
      </material>
    </visual>
    <collision>
      <origin xyz="0 0 0" rpy="0 0 0" />
      <geometry>
        <!-- <mesh filename="package://mz04/meshes/RR_hip.dae" /> -->
      </geometry>
    </collision>
  </link>
  <joint name="RR_hip_joint" type="revolute">
    <origin xyz="-0.22625 -0.07 0" rpy="0 0 0" />
    <parent link="trunk" />
    <child link="RR_hip" />
    <axis xyz="1 0 0" />
    <limit lower="-3.14" upper="3.14" effort="50" velocity="20" />
  </joint>
  <link name="RR_thigh">
    <inertial>
      <origin xyz="-0.00078925 -0.061044 -0.025566" rpy="0 0 0" />
      <mass value="0.72376" />
      <inertia ixx="0.0046259" ixy="-1.8596E-05" ixz="-1.1948E-05" iyy="0.0048648" iyz="-0.00058927" izz="0.001047" />
    </inertial>
    <visual>
      <origin xyz="0 0 0" rpy="0 0 0" />
      <geometry>
        <mesh filename="package://mz04/meshes/thigh.dae" />
      </geometry>
      <material name="">
        <color rgba="1 1 1 1" />
      </material>
    </visual>
    <collision>
      <origin xyz="0 0 0" rpy="0 0 0" />
      <geometry>
        <!-- <mesh filename="package://mz04/meshes/RR_thigh.dae" /> -->
      </geometry>
    </collision>
  </link>
  <joint name="RR_thigh_joint" type="revolute">
    <origin xyz="-0.08775 -0.02125 0" rpy="0 0 0" />
    <parent link="RR_hip" />
    <child link="RR_thigh" />
    <axis xyz="0 1 0" />
    <limit lower="-3.14" upper="3.14" effort="50" velocity="20" />
  </joint>
  <link name="RR_calf">
    <inertial>
      <origin xyz="-0.037767 -4.7349E-06 -0.17641" rpy="0 0 0" />
      <mass value="0.1253" />
      <inertia ixx="0.00096664" ixy="-1.5873E-08" ixz="-0.00015606" iyy="0.0010073" iyz="-1.3304E-08" izz="5.7049E-05" />
    </inertial>
    <visual>
      <origin xyz="0 0 0" rpy="0 0 0" />
      <geometry>
        <mesh filename="package://mz04/meshes/calf.dae" />
      </geometry>
      <material name="">
        <color rgba="1 1 1 1" />
      </material>
    </visual>
    <collision>
      <origin xyz="0 0 0" rpy="0 0 0" />
      <geometry>
        <!-- <mesh filename="package://mz04/meshes/RR_calf.dae" /> -->
      </geometry>
    </collision>
  </link>
  <joint name="RR_calf_joint" type="revolute">
    <origin xyz="0.022901 -0.09275 -0.29912" rpy="0 0 0" />
    <parent link="RR_thigh" />
    <child link="RR_calf" />
    <axis xyz="0 -1 0" />
    <limit lower="-3.14" upper="3.14" effort="50" velocity="20" />
  </joint>
  <link name="RL_hip">
    <inertial>
      <origin xyz="-0.083541 0.0016537 1.2994E-05" rpy="0 0 0" />
      <mass value="0.56406" />
      <inertia ixx="0.00061418" ixy="-3.2659E-06" ixz="-8.3078E-08" iyy="0.0011773" iyz="7.6935E-08" izz="0.00077313" />
    </inertial>
    <visual>
      <origin xyz="0 0 0" rpy="0 0 0" />
      <geometry>
        <mesh filename="package://mz04/meshes/RL_hip.dae" />
      </geometry>
      <material name="">
        <color rgba="1 1 1 1" />
      </material>
    </visual>
    <collision>
      <origin xyz="0 0 0" rpy="0 0 0" />
      <geometry>
        <!-- <mesh filename="package://mz04/meshes/RL_hip.dae" /> -->
      </geometry>
    </collision>
  </link>
  <joint name="RL_hip_joint" type="revolute">
    <origin xyz="-0.22625 0.07 0" rpy="0 0 0" />
    <parent link="trunk" />
    <child link="RL_hip" />
    <axis xyz="1 0 0" />
    <limit lower="-3.14" upper="3.14" effort="50" velocity="20" />
  </joint>
  <link name="RL_thigh">
    <inertial>
      <origin xyz="-0.00082867 0.061044 -0.025542" rpy="0 0 0" />
      <mass value="0.72376" />
      <inertia ixx="0.0046268" ixy="2.0164E-05" ixz="-2.0099E-05" iyy="0.0048657" iyz="0.00058953" izz="0.0010468" />
    </inertial>
    <visual>
      <origin xyz="0 0 0" rpy="0 0 0" />
      <geometry>
        <mesh filename="package://mz04/meshes/thigh_mirror.dae" />
      </geometry>
      <material name="">
        <color rgba="1 1 1 1" />
      </material>
    </visual>
    <collision>
      <origin xyz="0 0 0" rpy="0 0 0" />
      <geometry>
        <!-- <mesh filename="package://mz04/meshes/RL_thigh.dae" /> -->
      </geometry>
    </collision>
  </link>
  <joint name="RL_thigh_joint" type="revolute">
    <origin xyz="-0.08775 0.02125 0" rpy="0 0 0" />
    <parent link="RL_hip" />
    <child link="RL_thigh" />
    <axis xyz="0 -1 0" />
    <limit lower="-3.14" upper="3.14" effort="50" velocity="20" />
  </joint>
  <link name="RL_calf">
    <inertial>
      <origin xyz="-0.037767 -4.7357E-06 -0.17641" rpy="0 0 0" />
      <mass value="0.1253" />
      <inertia ixx="0.00096664" ixy="-1.5874E-08" ixz="-0.00015606" iyy="0.0010073" iyz="-1.3303E-08" izz="5.7049E-05" />
    </inertial>
    <visual>
      <origin xyz="0 0 0" rpy="0 0 0" />
      <geometry>
        <mesh filename="package://mz04/meshes/calf.dae" />
      </geometry>
      <material name="">
        <color rgba="1 1 1 1" />
      </material>
    </visual>
    <collision>
      <origin xyz="0 0 0" rpy="0 0 0" />
      <geometry>
        <!-- <mesh filename="package://mz04/meshes/calf.dae" /> -->
      </geometry>
    </collision>
  </link>
  <joint name="RL_calf_joint" type="revolute">
    <origin xyz="0.022238 0.09275 -0.29917" rpy="0 0 0" />
    <parent link="RL_thigh" />
    <child link="RL_calf" />
    <axis xyz="0 -1 0" />
    <limit lower="-3.14" upper="3.14" effort="50" velocity="20" />
  </joint>
</robot>