<?xml version="1.0" encoding="utf-8"?>
<!-- This URDF was automatically created by SolidWorks to URDF Exporter! Originally created by Stephen Brawner (brawner@gmail.com) 
     Commit Version: 1.5.1-0-g916b5db  Build Version: 1.5.7152.31018
     For more information, please see http://wiki.ros.org/sw_urdf_exporter -->
<robot
  name="qa01_description">
  <link
    name="base_link">
    <inertial>
      <origin
        xyz="0.00019565 -0.00016231 0.057496"
        rpy="0 0 0" />
      <mass
        value="2.8142" />
      <inertia
        ixx="0.0031136"
        ixy="-4.9945E-07"
        ixz="4.7914E-05"
        iyy="0.0029365"
        iyz="8.9155E-07"
        izz="0.0026818" />
    </inertial>
    <visual>
      <origin
        xyz="0 0 0"
        rpy="0 0 0" />
      <geometry>
        <mesh
          filename="package://qa01_description/meshes/base_link.STL" />
      </geometry>
      <material
        name="">
        <color
          rgba="0.75294 0.75294 0.75294 1" />
      </material>
    </visual>
    <collision>
      <origin
        xyz="0 0 0"
        rpy="0 0 0" />
      <geometry>
        <mesh
          filename="package://qa01_description/meshes/base_link.STL" />
      </geometry>
    </collision>
  </link>
  <link
    name="Link1">
    <inertial>
      <origin
        xyz="3.3791E-05 0.030742 0.030107"
        rpy="0 0 0" />
      <mass
        value="0.7547" />
      <inertia
        ixx="0.00097955"
        ixy="1.0431E-06"
        ixz="4.3103E-07"
        iyy="0.00091672"
        iyz="-0.00025756"
        izz="0.0008983" />
    </inertial>
    <visual>
      <origin
        xyz="0 0 0"
        rpy="0 0 0" />
      <geometry>
        <mesh
          filename="package://qa01_description/meshes/Link1.STL" />
      </geometry>
      <material
        name="">
        <color
          rgba="0.75294 0.75294 0.75294 1" />
      </material>
    </visual>
    <collision>
      <origin
        xyz="0 0 0"
        rpy="0 0 0" />
      <geometry>
        <mesh
          filename="package://qa01_description/meshes/Link1.STL" />
      </geometry>
    </collision>
  </link>
  <joint
    name="Joint1"
    type="revolute">
    <origin
      xyz="-0.00010406 0 0.1065"
      rpy="0 0 0" />
    <parent
      link="base_link" />
    <child
      link="Link1" />
    <axis
      xyz="0 0 -1" />
    <limit
      lower="-3.14"
      upper="3.14"
      effort="40"
      velocity="20" />
  </joint>
  <link
    name="Link2">
    <inertial>
      <origin
        xyz="-0.18479 -0.046183 0.003242"
        rpy="0 0 0" />
      <mass
        value="6.7869" />
      <inertia
        ixx="0.0050206"
        ixy="-0.00022611"
        ixz="0.00084336"
        iyy="0.056029"
        iyz="-1.3155E-06"
        izz="0.055819" />
    </inertial>
    <visual>
      <origin
        xyz="0 0 0"
        rpy="0 0 0" />
      <geometry>
        <mesh
          filename="package://qa01_description/meshes/Link2.STL" />
      </geometry>
      <material
        name="">
        <color
          rgba="0.75294 0.75294 0.75294 1" />
      </material>
    </visual>
    <collision>
      <origin
        xyz="0 0 0"
        rpy="0 0 0" />
      <geometry>
        <mesh
          filename="package://qa01_description/meshes/Link2.STL" />
      </geometry>
    </collision>
  </link>
  <joint
    name="Joint2"
    type="revolute">
    <origin
      xyz="0 0.0412 0.058"
      rpy="0 0 0" />
    <parent
      link="Link1" />
    <child
      link="Link2" />
    <axis
      xyz="0 -1 0" />
    <limit
      lower="-3.14"
      upper="3.14"
      effort="40"
      velocity="20" />
  </joint>
  <link
    name="Link3">
    <inertial>
      <origin
        xyz="0.078459 -0.026984 0.071435"
        rpy="0 0 0" />
      <mass
        value="3.1428" />
      <inertia
        ixx="0.0031768"
        ixy="0.00021674"
        ixz="-0.00099646"
        iyy="0.005396"
        iyz="0.00024749"
        izz="0.003895" />
    </inertial>
    <visual>
      <origin
        xyz="0 0 0"
        rpy="0 0 0" />
      <geometry>
        <mesh
          filename="package://qa01_description/meshes/Link3.STL" />
      </geometry>
      <material
        name="">
        <color
          rgba="0.75294 0.75294 0.75294 1" />
      </material>
    </visual>
    <collision>
      <origin
        xyz="0 0 0"
        rpy="0 0 0" />
      <geometry>
        <mesh
          filename="package://qa01_description/meshes/Link3.STL" />
      </geometry>
    </collision>
  </link>
  <joint
    name="Joint3"
    type="revolute">
    <origin
      xyz="-0.40994 -0.0095 0.0068851"
      rpy="0 0 0" />
    <parent
      link="Link2" />
    <child
      link="Link3" />
    <axis
      xyz="0 -1 0" />
    <limit
      lower="-3.14"
      upper="3.14"
      effort="40"
      velocity="20" />
  </joint>
  <link
    name="Link4">
    <inertial>
      <origin
        xyz="0.19593 -0.0045978 -0.0032786"
        rpy="0 0 0" />
      <mass
        value="3.5217" />
      <inertia
        ixx="0.0024215"
        ixy="-0.00014283"
        ixz="0.00017413"
        iyy="0.012898"
        iyz="4.3928E-06"
        izz="0.012748" />
    </inertial>
    <visual>
      <origin
        xyz="0 0 0"
        rpy="0 0 0" />
      <geometry>
        <mesh
          filename="package://qa01_description/meshes/Link4.STL" />
      </geometry>
      <material
        name="">
        <color
          rgba="0.75294 0.75294 0.75294 1" />
      </material>
    </visual>
    <collision>
      <origin
        xyz="0 0 0"
        rpy="0 0 0" />
      <geometry>
        <mesh
          filename="package://qa01_description/meshes/Link4.STL" />
      </geometry>
    </collision>
  </link>
  <joint
    name="Joint4"
    type="revolute">
    <origin
      xyz="0.14291 -0.0315 0.082612"
      rpy="0 0 0" />
    <parent
      link="Link3" />
    <child
      link="Link4" />
    <axis
      xyz="-0.99986 0 0.016793" />
    <limit
      lower="-3.14"
      upper="3.14"
      effort="40"
      velocity="20" />
  </joint>
  <link
    name="Link5">
    <inertial>
      <origin
        xyz="0.077685 -0.029029 -0.0013708"
        rpy="0 0 0" />
      <mass
        value="2.8379" />
      <inertia
        ixx="0.0019352"
        ixy="0.00025154"
        ixz="1.9753E-05"
        iyy="0.0035651"
        iyz="-5.9651E-06"
        izz="0.003187" />
    </inertial>
    <visual>
      <origin
        xyz="0 0 0"
        rpy="0 0 0" />
      <geometry>
        <mesh
          filename="package://qa01_description/meshes/Link5.STL" />
      </geometry>
      <material
        name="">
        <color
          rgba="0.75294 0.75294 0.75294 1" />
      </material>
    </visual>
    <collision>
      <origin
        xyz="0 0 0"
        rpy="0 0 0" />
      <geometry>
        <mesh
          filename="package://qa01_description/meshes/Link5.STL" />
      </geometry>
    </collision>
  </link>
  <joint
    name="Joint5"
    type="revolute">
    <origin
      xyz="0.24926 0.0355 -0.0041864"
      rpy="0 0 0" />
    <parent
      link="Link4" />
    <child
      link="Link5" />
    <axis
      xyz="0 -1 0" />
    <limit
      lower="-3.14"
      upper="3.14"
      effort="40"
      velocity="20" />
  </joint>
  <link
    name="Link6">
    <inertial>
      <origin
        xyz="0.083496 0.0006627 -0.0088587"
        rpy="0 0 0" />
      <mass
        value="2.9064" />
      <inertia
        ixx="0.0014442"
        ixy="-1.915E-06"
        ixz="0.00034941"
        iyy="0.0033645"
        iyz="1.6152E-06"
        izz="0.0031518" />
    </inertial>
    <visual>
      <origin
        xyz="0 0 0"
        rpy="0 0 0" />
      <geometry>
        <mesh
          filename="package://qa01_description/meshes/Link6.STL" />
      </geometry>
      <material
        name="">
        <color
          rgba="0.75294 0.75294 0.75294 1" />
      </material>
    </visual>
    <collision>
      <origin
        xyz="0 0 0"
        rpy="0 0 0" />
      <geometry>
        <mesh
          filename="package://qa01_description/meshes/Link6.STL" />
      </geometry>
    </collision>
  </link>
  <joint
    name="Joint6"
    type="revolute">
    <origin
      xyz="0.13148 -0.0355 -0.0022083"
      rpy="0 0 0" />
    <parent
      link="Link5" />
    <child
      link="Link6" />
    <axis
      xyz="-0.99986 0 0.016793" />
    <limit
      lower="-3.14"
      upper="3.14"
      effort="40"
      velocity="20" />
  </joint>
  <link
    name="Link7">
    <inertial>
      <origin
        xyz="0.055531 -0.032158 0.005474"
        rpy="0 0 0" />
      <mass
        value="1.0569" />
      <inertia
        ixx="0.00036595"
        ixy="-1.0269E-05"
        ixz="0.00031068"
        iyy="0.0017974"
        iyz="1.4328E-06"
        izz="0.0016977" />
    </inertial>
    <visual>
      <origin
        xyz="0 0 0"
        rpy="0 0 0" />
      <geometry>
        <mesh
          filename="package://qa01_description/meshes/Link7.STL" />
      </geometry>
      <material
        name="">
        <color
          rgba="0.75294 0.75294 0.75294 1" />
      </material>
    </visual>
    <collision>
      <origin
        xyz="0 0 0"
        rpy="0 0 0" />
      <geometry>
        <mesh
          filename="package://qa01_description/meshes/Link7.STL" />
      </geometry>
    </collision>
  </link>
  <joint
    name="Joint7"
    type="revolute">
    <origin
      xyz="0.10136 0.0322 0.020301"
      rpy="0 0 0" />
    <parent
      link="Link6" />
    <child
      link="Link7" />
    <axis
      xyz="0 -1 0" />
    <limit
      lower="-3.14"
      upper="3.14"
      effort="40"
      velocity="20" />
  </joint>
</robot>