<?xml version="1.0" encoding="utf-8"?>
<!-- This URDF was automatically created by SolidWorks to URDF Exporter! Originally created by
Stephen Brawner (brawner@gmail.com) 
     Commit Version: 1.5.1-0-g916b5db  Build Version: 1.5.7152.31018
     For more information, please see http://wiki.ros.org/sw_urdf_exporter -->
<robot name="seven">
    <link name="world" />
    <joint name="world_fixed" type="fixed">
        <parent link="world" />
        <child link="base_link" />
    </joint>
    <link name="base_link">
        <inertial>
            <origin xyz="-0.00097015 -2.3069E-05 0.08519" rpy="0 0 0" />
            <mass value="6.0874" />
            <inertia ixx="0.010456" ixy="-4.186E-07" ixz="7.1158E-05" iyy="0.010367" iyz="-4.2042E-06" izz="0.0091575" />
        </inertial>
        <visual>
            <origin xyz="0 0 0" rpy="0 0 0" />
            <geometry>
                <mesh filename="package://seven_description/meshes/base_link.STL" />
            </geometry>
            <material name="">
                <color rgba="0.75294 0.75294 0.75294 1" />
            </material>
        </visual>
        <collision>
            <origin xyz="0 0 0" rpy="0 0 0" />
            <geometry>
                <mesh filename="package://seven_description/meshes/base_link.STL" />
            </geometry>
        </collision>
    </link>
    <link name="Link1">
        <inertial>
            <origin xyz="-1.0056E-05 0.0060012 0.11375" rpy="0 0 0" />
            <mass value="5.6058" />
            <inertia ixx="0.011539" ixy="-5.2562E-06" ixz="-6.5028E-07" iyy="0.0096037" iyz="1.0132E-05" izz="0.0066658" />
        </inertial>
        <visual>
            <origin xyz="0 0 0" rpy="0 0 0" />
            <geometry>
                <mesh filename="package://seven_description/meshes/Link1.STL" />
            </geometry>
            <material name="">
                <color rgba="0.75294 0.75294 0.75294 1" />
            </material>
        </visual>
        <collision>
            <origin xyz="0 0 0" rpy="0 0 0" />
            <geometry>
                <mesh filename="package://seven_description/meshes/Link1.STL" />
            </geometry>
        </collision>
    </link>
    <joint name="Joint1" type="revolute">
        <origin xyz="-4.6123E-05 0 0.14575" rpy="0 0 0" />
        <parent link="base_link" />
        <child link="Link1" />
        <axis xyz="0 0 1" />
        <limit lower="-3.14" upper="3.14" effort="40" velocity="40" />
    </joint>
    <link name="Link2">
        <inertial>
            <origin xyz="-0.00018434 0.036866 0.14807" rpy="0 0 0" />
            <mass value="3.9468" />
            <inertia ixx="0.012537" ixy="-1.85E-06" ixz="-1.255E-05" iyy="0.011431" iyz="-0.0022653" izz="0.0034705" />
        </inertial>
        <visual>
            <origin xyz="0 0 0" rpy="0 0 0" />
            <geometry>
                <mesh filename="package://seven_description/meshes/Link2.STL" />
            </geometry>
            <material name="">
                <color rgba="0.75294 0.75294 0.75294 1" />
            </material>
        </visual>
        <collision>
            <origin xyz="0 0 0" rpy="0 0 0" />
            <geometry>
                <mesh filename="package://seven_description/meshes/Link2.STL" />
            </geometry>
        </collision>
    </link>
    <joint name="Joint2" type="revolute">
        <origin xyz="3.5999E-05 -0.045 0.12625" rpy="0 0 0" />
        <parent link="Link1" />
        <child link="Link2" />
        <axis xyz="0.00079998 -1 0" />
        <limit lower="-3.14" upper="3.14" effort="40" velocity="40" />
    </joint>
    <link name="Link3">
        <inertial>
            <origin xyz="-4.7584E-05 0.004404 0.11108" rpy="0 0 0" />
            <mass value="3.8727" />
            <inertia ixx="0.0071633" ixy="-5.3054E-08" ixz="3.206E-06" iyy="0.0059131" iyz="-7.2511E-05" izz="0.0036398" />
        </inertial>
        <visual>
            <origin xyz="0 0 0" rpy="0 0 0" />
            <geometry>
                <mesh filename="package://seven_description/meshes/Link3.STL" />
            </geometry>
            <material name="">
                <color rgba="0.75294 0.75294 0.75294 1" />
            </material>
        </visual>
        <collision>
            <origin xyz="0 0 0" rpy="0 0 0" />
            <geometry>
                <mesh filename="package://seven_description/meshes/Link3.STL" />
            </geometry>
        </collision>
    </link>
    <joint name="Joint3" type="revolute">
        <origin xyz="-3.6799E-05 0.046 0.22575" rpy="0 0 0" />
        <parent link="Link2" />
        <child link="Link3" />
        <axis xyz="0 0 1" />
        <limit lower="-3.14" upper="3.14" effort="40" velocity="40" />
    </joint>
    <link name="Link4">
        <inertial>
            <origin xyz="-0.00019023 0.033489 0.13532" rpy="0 0 0" />
            <mass value="3.0629" />
            <inertia ixx="0.0078569" ixy="-2.8823E-07" ixz="-9.4457E-06" iyy="0.0071861" iyz="-0.0014418" izz="0.0022407" />
        </inertial>
        <visual>
            <origin xyz="0 0 0" rpy="0 0 0" />
            <geometry>
                <mesh filename="package://seven_description/meshes/Link4.STL" />
            </geometry>
            <material name="">
                <color rgba="0.75294 0.75294 0.75294 1" />
            </material>
        </visual>
        <collision>
            <origin xyz="0 0 0" rpy="0 0 0" />
            <geometry>
                <mesh filename="package://seven_description/meshes/Link4.STL" />
            </geometry>
        </collision>
    </link>
    <joint name="Joint4" type="revolute">
        <origin xyz="3.2799E-05 -0.041 0.13025" rpy="0 0 0" />
        <parent link="Link3" />
        <child link="Link4" />
        <axis xyz="0.00079998 -1 0" />
        <limit lower="-3.14" upper="3.14" effort="40" velocity="40" />
    </joint>
    <link name="Link5">
        <inertial>
            <origin xyz="-5.7877E-05 0.0064327 0.11158" rpy="0 0 0" />
            <mass value="3.1833" />
            <inertia ixx="0.00608" ixy="-3.0909E-07" ixz="2.6506E-06" iyy="0.0051687" iyz="-9.4675E-05" izz="0.0025245" />
        </inertial>
        <visual>
            <origin xyz="0 0 0" rpy="0 0 0" />
            <geometry>
                <mesh filename="package://seven_description/meshes/Link5.STL" />
            </geometry>
            <material name="">
                <color rgba="0.75294 0.75294 0.75294 1" />
            </material>
        </visual>
        <collision>
            <origin xyz="0 0 0" rpy="0 0 0" />
            <geometry>
                <mesh filename="package://seven_description/meshes/Link5.STL" />
            </geometry>
        </collision>
    </link>
    <joint name="Joint5" type="revolute">
        <origin xyz="-3.3599E-05 0.042 0.207" rpy="0 0 0" />
        <parent link="Link4" />
        <child link="Link5" />
        <axis xyz="0 0 1" />
        <limit lower="-3.14" upper="3.14" effort="40" velocity="40" />
    </joint>
    <link name="Link6">
        <inertial>
            <origin xyz="-0.00016131 0.032352 0.10956" rpy="0 0 0" />
            <mass value="2.8582" />
            <inertia ixx="0.0050585" ixy="-5.6132E-08" ixz="-5.8848E-06" iyy="0.0045189" iyz="-0.00082277" izz="0.0020086" />
        </inertial>
        <visual>
            <origin xyz="0 0 0" rpy="0 0 0" />
            <geometry>
                <mesh filename="package://seven_description/meshes/Link6.STL" />
            </geometry>
            <material name="">
                <color rgba="0.75294 0.75294 0.75294 1" />
            </material>
        </visual>
        <collision>
            <origin xyz="0 0 0" rpy="0 0 0" />
            <geometry>
                <mesh filename="package://seven_description/meshes/Link6.STL" />
            </geometry>
        </collision>
    </link>
    <joint name="Joint6" type="revolute">
        <origin xyz="2.9599E-05 -0.037 0.135" rpy="0 0 0" />
        <parent link="Link5" />
        <child link="Link6" />
        <axis xyz="0.00079998 -1 0" />
        <limit lower="-3.14" upper="3.14" effort="40" velocity="40" />
    </joint>
    <link name="Link7">
        <inertial>
            <origin xyz="-0.00072494 0.0012294 0.012556" rpy="0 0 0" />
            <mass value="0.68833" />
            <inertia ixx="0.00038081" ixy="4.1712E-07" ixz="1.296E-06" iyy="0.00038415" iyz="5.1446E-07" izz="0.00057887" />
        </inertial>
        <visual>
            <origin xyz="0 0 0" rpy="0 0 0" />
            <geometry>
                <mesh filename="package://seven_description/meshes/Link7.STL" />
            </geometry>
            <material name="">
                <color rgba="0.75294 0.75294 0.75294 1" />
            </material>
        </visual>
        <collision>
            <origin xyz="0 0 0" rpy="0 0 0" />
            <geometry>
                <mesh filename="package://seven_description/meshes/Link7.STL" />
            </geometry>
        </collision>
    </link>
    <joint name="Joint7" type="revolute">
        <origin xyz="-3.0399E-05 0.038 0.17" rpy="0 0 0" />
        <parent link="Link6" />
        <child link="Link7" />
        <axis xyz="0 0 1" />
        <limit lower="-3.14" upper="3.14" effort="40" velocity="40" />
    </joint>
    <transmission name="trans_Joint1">
        <type>transmission_interface/SimpleTransmission</type>
        <joint name="Joint1">
            <hardwareInterface>hardware_interface/PositionJointInterface</hardwareInterface>
        </joint>
        <actuator name="Joint1_motor">
            <hardwareInterface>hardware_interface/PositionJointInterface</hardwareInterface>
            <mechanicalReduction>1</mechanicalReduction>
        </actuator>
    </transmission>
    <transmission name="trans_Joint2">
        <type>transmission_interface/SimpleTransmission</type>
        <joint name="Joint2">
            <hardwareInterface>hardware_interface/PositionJointInterface</hardwareInterface>
        </joint>
        <actuator name="Joint2_motor">
            <hardwareInterface>hardware_interface/PositionJointInterface</hardwareInterface>
            <mechanicalReduction>1</mechanicalReduction>
        </actuator>
    </transmission>
    <transmission name="trans_Joint3">
        <type>transmission_interface/SimpleTransmission</type>
        <joint name="Joint3">
            <hardwareInterface>hardware_interface/PositionJointInterface</hardwareInterface>
        </joint>
        <actuator name="Joint3_motor">
            <hardwareInterface>hardware_interface/PositionJointInterface</hardwareInterface>
            <mechanicalReduction>1</mechanicalReduction>
        </actuator>
    </transmission>
    <transmission name="trans_Joint4">
        <type>transmission_interface/SimpleTransmission</type>
        <joint name="Joint4">
            <hardwareInterface>hardware_interface/PositionJointInterface</hardwareInterface>
        </joint>
        <actuator name="Joint4_motor">
            <hardwareInterface>hardware_interface/PositionJointInterface</hardwareInterface>
            <mechanicalReduction>1</mechanicalReduction>
        </actuator>
    </transmission>
    <transmission name="trans_Joint5">
        <type>transmission_interface/SimpleTransmission</type>
        <joint name="Joint5">
            <hardwareInterface>hardware_interface/PositionJointInterface</hardwareInterface>
        </joint>
        <actuator name="Joint5_motor">
            <hardwareInterface>hardware_interface/PositionJointInterface</hardwareInterface>
            <mechanicalReduction>1</mechanicalReduction>
        </actuator>
    </transmission>
    <transmission name="trans_Joint6">
        <type>transmission_interface/SimpleTransmission</type>
        <joint name="Joint6">
            <hardwareInterface>hardware_interface/PositionJointInterface</hardwareInterface>
        </joint>
        <actuator name="Joint6_motor">
            <hardwareInterface>hardware_interface/PositionJointInterface</hardwareInterface>
            <mechanicalReduction>1</mechanicalReduction>
        </actuator>
    </transmission>
    <transmission name="trans_Joint7">
        <type>transmission_interface/SimpleTransmission</type>
        <joint name="Joint7">
            <hardwareInterface>hardware_interface/PositionJointInterface</hardwareInterface>
        </joint>
        <actuator name="Joint7_motor">
            <hardwareInterface>hardware_interface/PositionJointInterface</hardwareInterface>
            <mechanicalReduction>1</mechanicalReduction>
        </actuator>
    </transmission>
    <gazebo>
        <plugin name="gazebo_ros_control" filename="libgazebo_ros_control.so">
            <robotNamespace>/</robotNamespace>
        </plugin>
    </gazebo>
</robot>