<?xml version="1.0"?>

<robot name= "sz"
    xmlns:xacro="http://www.ros.org/wiki/xacro">

    <xacro:arg name="DEBUG" default="false"/>

    <!-- <xacro:include filename="$(find sz_description)/xacro/leg.xacro"/> -->
    <xacro:include filename="$(find sz_description)/xacro/transmission.xacro"/>
    <xacro:include filename="$(find sz_description)/xacro/gazebo.xacro"/>

    <material name="blue">
        <color rgba="0.0 0.0 0.8 1.0"/>
    </material>
    
    <material name="green">
        <color rgba="0.0 0.8 0.0 1.0"/>
    </material>
    
    <material name="silver">
        <color rgba="0.913725490196 0.913725490196 0.847058823529 0.5"/>
    </material>
    
    <material name="red">
        <color rgba="0.8 0.0 0.0 1.0"/>
    </material>

    <xacro:if value="$(arg DEBUG)">
        <link name="world"/>
        <joint name="base_static_joint" type="fixed">
            <origin rpy="0 0 0" xyz="0 0 0"/>
            <parent link="world"/>
            <child link="base"/>
        </joint>
    </xacro:if>

    <link name="base">
        <visual>
        <origin rpy="0 0 0" xyz="0 0 0"/>
        <geometry>
            <box size="0.001 0.001 0.001"/>
        </geometry>
        </visual>
    </link>
    <joint name="floating_base" type="fixed">
        <origin rpy="0 0 0" xyz="0 0 0"/>
        <parent link="base"/>
        <child link="trunk"/>
    </joint>
    <link name="trunk">
        <visual>
        <origin rpy="0 0 0" xyz="0 0 0"/>
        <geometry>
            <mesh filename="package://sz_description/meshes/trunk.dae" scale="1 1 1"/>
        </geometry>
        <material name="silver"/>
        </visual>
        <collision>
        <origin rpy="0 0 0" xyz="0 0 0"/>
        <geometry>
            <box size="0.286 0.206 0.120"/>
        </geometry>
        </collision>
        <inertial>
        <!-- <origin rpy="0 0 0" xyz="0.012731 0.002186 0.000515"/> -->
        <origin rpy="0 0 0" xyz="0.0 0.0 0.0"/>
        <mass value="5.848"/>
        <inertia ixx="0.0265" ixy="0.0" ixz="0.0" iyy="0.04660" iyz="0.0" izz="0.05907"/>
        <!-- <inertia ixx="0.01883039838" ixy="-0.00025723812" ixz="-0.00032987281" iyy="0.0705707128" iyz="-0.00004689787" izz="0.0802532948" /> -->
        </inertial>
    </link>


    <joint name="head_joint" type="fixed">
        <parent link="trunk"/>
        <child link="head"/>
        <origin rpy="0 0 0" xyz="0.29 0 0"/>
    </joint>
    <link name="head">
        <collision>
        <origin rpy="0 0 0" xyz="0 0 0"/>
        <geometry>
            <box size="0.06 0.13 0.120"/>
        </geometry>
        </collision>
    </link>
    

    <joint name="imu_joint" type="fixed">
        <parent link="trunk"/>
        <child link="imu_link"/>
        <origin rpy="0 0 0" xyz="0 0 0"/>
    </joint>
    <link name="imu_link">
        <inertial>
        <mass value="0.001"/>
        <origin rpy="0 0 0" xyz="0 0 0"/>
        <!-- <inertia ixx="0.0001" ixy="0" ixz="0" iyy="0.0001" iyz="0" izz="0.0001"/> -->
        <inertia ixx="0.000001" ixy="0" ixz="0" iyy="0.000001" iyz="0" izz="0.000001"/>
        </inertial>
        <visual>
        <origin rpy="0 0 0" xyz="0 0 0"/>
        <geometry>
            <box size="0.001 0.001 0.001"/>
        </geometry>
        <material name="silver"/>
        </visual>
        <!-- <collision>
        <origin rpy="0 0 0" xyz="0 0 0"/>
        <geometry>
            <box size=".001 .001 .001"/>
        </geometry>
        </collision> -->
    </link>
    <joint name="FR_hip_joint" type="revolute">
        <origin rpy="0 0 0" xyz="0.1995 -0.05001 0"/>
        <parent link="trunk"/>
        <child link="FR_hip"/>
        <axis xyz="1 0 0"/>
        <dynamics damping="0" friction="0"/>
        <!-- <limit effort="20" lower="-0.802851455917" upper="0.802851455917" velocity="52.4"/> -->
        <limit effort="18" lower="-0.94" upper="0.94" velocity="40"/>
    </joint>
    <link name="FR_hip">
        <visual>
        <!-- <origin rpy="3.14159265359 0 0" xyz="0 0 0"/> -->
        <origin xyz="0 0 0" rpy="0 0 0" />
        <geometry>
            <mesh filename="package://sz_description/meshes/FR_hip.dae" scale="1 1 1"/>
        </geometry>
        <material name="silver"/>
        </visual>
        <!-- <collision>
        <origin rpy="1.57079632679 0 0" xyz="0 0 0"/>
        <geometry>
            <cylinder length="0.04" radius="0.046"/>
        </geometry>
        </collision> -->
        <inertial>
        <origin rpy="0 0 0" xyz="0.0037743 -0.0038894 7.8535E-05"/>
        <mass value="0.68"/>
        <inertia ixx="0.000469246" ixy="9.409e-06" ixz="-3.42e-07" iyy="0.00080749" iyz="4.66e-07" izz="0.000552929"/>
        <!-- <inertia ixx="4.602822857142857e-4" ixy="9.953142857142857e-6" ixz="-3.394285714285714e-7" iyy="7.898548571428571e-4" iyz="6.228571428571429e-7" izz="5.576217142857143e-4" /> -->
        </inertial>
    </link>
    <joint name="FR_hip_fixed" type="fixed">
        <origin rpy="0 0 0" xyz="0 -0.081 0"/>
        <parent link="FR_hip"/>
        <child link="FR_thigh_shoulder"/>
    </joint>
    <!-- this link is only for collision -->
    <link name="FR_thigh_shoulder">
        <!-- <collision>
        <origin rpy="1.57079632679 0 0" xyz="0 0 0"/>
        <geometry>
            <cylinder length="0.032" radius="0.041"/>
        </geometry>
        </collision> -->
    </link>
    <joint name="FR_thigh_joint" type="revolute">
        <origin rpy="0 0 0" xyz="0 -0.08505 0"/>
        <parent link="FR_hip"/>
        <child link="FR_thigh"/>
        <axis xyz="0 1 0"/>
        <dynamics damping="0" friction="0"/>
        <!-- <limit effort="55" lower="-1.0471975512" upper="4.18879020479" velocity="28.6"/> -->
        <!-- <limit effort="18" lower="-2.35" upper="1.81" velocity="40"/> -->
        <limit effort="18" lower="-0.409203673" upper="3.550796326" velocity="40"/>
    </joint>
    <link name="FR_thigh">
        <visual>
        <origin rpy="0 0 0" xyz="0 0 0"/>
        <geometry>
            <mesh filename="package://sz_description/meshes/thigh.dae" scale="1 1 1"/>
        </geometry>
        <material name="silver"/>
        </visual>
        <!-- <collision>
        <origin rpy="0 1.57079632679 0" xyz="0 0 -0.1"/>
        <geometry>
            <box size="0.2 0.0245 0.034"/>
        </geometry>
        </collision> -->
        <collision>
        <origin xyz="0 0 -0.1" rpy="0 0 0" />
        <geometry>
            <box size="0.03 0.03 0.2"/>
        </geometry>
        </collision>
        <inertial>
        <origin rpy="0 0 0" xyz="-0.0025418 0.024397 -0.017202"/>
        <mass value="1.009"/>
        <inertia ixx="0.006118" ixy="0.0" ixz="0.0" iyy="0.006749" iyz="0.0" izz="0.001051"/>
        <!-- <inertia ixx="0.0059674237094595" ixy="2.463414414414414e-6" ixz="3.941565326576577e-4" iyy="0.0056818460304054" iyz="3.201302477477477e-5" izz="0.0012614772522523" /> -->
        </inertial>
    </link>
    <joint name="FR_calf_joint" type="revolute">
        <origin rpy="0 0 0" xyz="0 -0.0001 -0.2"/>
        <parent link="FR_thigh"/>
        <child link="FR_calf"/>
        <axis xyz="0 1 0"/>
        <dynamics damping="0" friction="0"/>
        <!-- <limit effort="55" lower="-2.69653369433" upper="-0.916297857297" velocity="28.6"/> -->
        <limit effort="27" lower="-2.6" upper="-0.885" velocity="26.6"/>
    </joint>
    <link name="FR_calf">
        <visual>
        <origin rpy="0 0 0" xyz="0 0 0"/>
        <geometry>
            <mesh filename="package://sz_description/meshes/calf.dae" scale="1 1 1"/>
        </geometry>
        <material name="silver"/>
        </visual>
        <!-- <collision>
        <origin rpy="0 1.57079632679 0" xyz="0 0 -0.1"/>
        <geometry>
            <box size="0.2 0.016 0.016"/>
        </geometry>
        </collision> -->
        <collision>
        <origin xyz="0 0 -0.1" rpy="0 0 0" />
        <geometry>
            <box size="0.02 0.02 0.2"/>
            <!-- <mesh filename="package://sz_description/meshes/calf.dae" /> -->
        </geometry>
        </collision>
        <inertial>
        <origin rpy="0 0 0" xyz="0.0052583 3.7921E-08 -0.11963"/>
        <mass value="0.224"/>
        <inertia ixx="0.001269" ixy="0.0" ixz="0.0" iyy="0.001277" iyz="0.0" izz="0.00002425"/>
        <!-- <inertia ixx="0.0034783165033113" ixy="0.0" ixz="-2.095735099337748e-4" iyy="0.0035020471523179" iyz="0.0" izz="4.622113907284768e-5" /> -->
        </inertial>
    </link>
    <joint name="FR_foot_fixed" type="fixed" dont_collapse="true">
        <origin rpy="0 0 0" xyz="0 0 -0.2"/>
        <parent link="FR_calf"/>
        <child link="FR_foot"/>
    </joint>
    <link name="FR_foot">
        <visual>
        <origin rpy="0 0 0" xyz="0 0 0"/>
        <geometry>
            <sphere radius="0.01"/>
        </geometry>
        <material name="silver"/>
        </visual>
        <collision>
        <origin rpy="0 0 0" xyz="0 0 0"/>
        <geometry>
            <!-- <sphere radius="0.02"/> -->
            <sphere radius="0.025"/>
        </geometry>
        </collision>
        <inertial>
        <mass value="0.06"/>
        <!-- the same as a1 -->
        <inertia ixx="9.6e-06" ixy="0.0" ixz="0.0" iyy="9.6e-06" iyz="0.0" izz="9.6e-06"/>
        </inertial>
    </link>
    <joint name="FL_hip_joint" type="revolute">
        <origin rpy="0 0 0" xyz="0.1995 0.05001 0"/>
        <parent link="trunk"/>
        <child link="FL_hip"/>
        <axis xyz="1 0 0"/>
        <dynamics damping="0" friction="0"/>
        <!-- <limit effort="20" lower="-0.802851455917" upper="0.802851455917" velocity="52.4"/> -->
        <limit effort="18" lower="-0.94" upper="0.94" velocity="40"/>
    </joint>
    <link name="FL_hip">
        <visual>
        <!-- the same as a1 -->
        <origin rpy="0 0 0" xyz="0 0 0"/>
        <geometry>
            <mesh filename="package://sz_description/meshes/FL_hip.dae" scale="1 1 1"/>
        </geometry>
        <material name="silver"/>
        </visual>
        <!-- <collision> 
        <origin rpy="1.57079632679 0 0" xyz="0 0 0"/>
        <geometry>
            <cylinder length="0.04" radius="0.046"/>
        </geometry>
        </collision> -->
        <inertial>
        <origin rpy="0 0 0" xyz="0.0037743 0.0038894 7.8535E-05"/>
        <mass value="0.68"/>
        <inertia ixx="0.000469246" ixy="9.409e-06" ixz="-3.42e-07" iyy="0.00080749" iyz="4.66e-07" izz="0.000552929"/>
        <!-- <inertia ixx="4.602822857142857e-4" ixy="-9.953142857142857e-6" ixz="-3.394285714285714e-7" iyy="7.898548571428571e-4" iyz="-6.228571428571429e-7" izz="5.576217142857143e-4" /> -->
        </inertial>
    </link>
    <joint name="FL_hip_fixed" type="fixed">
        <origin rpy="0 0 0" xyz="0 0.081 0"/>
        <parent link="FL_hip"/>
        <child link="FL_thigh_shoulder"/>
    </joint>
    <!-- this link is only for collision -->
    <link name="FL_thigh_shoulder">
        <!-- <collision>
        <origin rpy="1.57079632679 0 0" xyz="0 0 0"/>
        <geometry>
            <cylinder length="0.032" radius="0.041"/>
        </geometry>
        </collision> -->
    </link>
    <joint name="FL_thigh_joint" type="revolute">
        <origin rpy="0 0 0" xyz="0 0.08505 0"/>
        <parent link="FL_hip"/>
        <child link="FL_thigh"/>
        <axis xyz="0 1 0"/>
        <dynamics damping="0" friction="0"/>
        <!-- <limit effort="55" lower="-1.0471975512" upper="4.18879020479" velocity="28.6"/> -->
        <!-- <limit effort="18" lower="-2.35" upper="1.81" velocity="40"/> -->
        <limit effort="18" lower="-0.409203673" upper="3.550796326" velocity="40"/>
    </joint>
    <link name="FL_thigh">
        <visual>
        <origin rpy="0 0 0" xyz="0 0 0"/>
        <geometry>
            <mesh filename="package://sz_description/meshes/thigh_mirror.dae" scale="1 1 1"/>
        </geometry>
        <material name="silver"/>
        </visual>
        <!-- <collision>
        <origin rpy="0 1.57079632679 0" xyz="0 0 -0.1"/>
        <geometry>
            <box size="0.2 0.0245 0.034"/>
        </geometry>
        </collision> -->
        <collision>
        <origin xyz="0 0 -0.1" rpy="0 0 0" />
        <geometry>
            <box size="0.03 0.03 0.2"/>
        </geometry>
        </collision>
        <inertial>
        <origin rpy="0 0 0" xyz="-0.002926 -0.024388 -0.017656"/>
        <mass value="1.009"/>
        <inertia ixx="0.006118" ixy="0.0" ixz="0.0" iyy="0.006749" iyz="0.0" izz="0.001051"/>
        <!-- <inertia ixx="0.0059674237094595" ixy="-2.463414414414414e-6" ixz="3.941565326576577e-4" iyy="0.0056818460304054" iyz="-3.201302477477477e-5" izz="0.0012614772522523" /> -->
        </inertial>
    </link>
    <joint name="FL_calf_joint" type="revolute">
        <origin rpy="0 0 0" xyz="0 -0.0001 -0.2"/>
        <parent link="FL_thigh"/>
        <child link="FL_calf"/>
        <axis xyz="0 1 0"/>
        <dynamics damping="0" friction="0"/>
        <!-- <limit effort="55" lower="-2.69653369433" upper="-0.916297857297" velocity="28.6"/> -->
        <limit effort="27" lower="-2.6" upper="-0.885" velocity="26.6"/>
    </joint>
    <link name="FL_calf">
        <visual>
        <origin rpy="0 0 0" xyz="0 0 0"/>
        <geometry>
            <mesh filename="package://sz_description/meshes/calf.dae" scale="1 1 1"/>
        </geometry>
        <material name="silver"/>
        </visual>
        <!-- <collision>
        <origin rpy="0 1.57079632679 0" xyz="0 0 -0.1"/>
        <geometry>
            <box size="0.2 0.016 0.016"/>
        </geometry>
        </collision> -->
        <collision>
        <origin xyz="0 0 -0.1" rpy="0 0 0" />
        <geometry>
            <box size="0.02 0.02 0.2"/>
        </geometry>
        </collision>
        <inertial>
        <origin rpy="0 0 0" xyz="0.0052583 3.7881E-08 -0.11963"/>
        <mass value="0.224"/>
        <inertia ixx="0.001269" ixy="0.0" ixz="0.0" iyy="0.001277" iyz="0.0" izz="0.00002425"/>
        <!-- <inertia ixx="0.0034783165033113" ixy="0.0" ixz="-2.095735099337748e-4" iyy="0.0035020471523179" iyz="0.0" izz="4.622113907284768e-5" /> -->
        </inertial>
    </link>
    <joint name="FL_foot_fixed" type="fixed" dont_collapse="true">
        <origin rpy="0 0 0" xyz="0 0 -0.2"/>
        <parent link="FL_calf"/>
        <child link="FL_foot"/>
    </joint>
    <link name="FL_foot">
        <visual>
        <origin rpy="0 0 0" xyz="0 0 0"/>
        <geometry>
            <sphere radius="0.01"/>
        </geometry>
        <material name="silver"/>
        </visual>
        <collision>
        <origin rpy="0 0 0" xyz="0 0 0"/>
        <geometry>
            <!-- <sphere radius="0.02"/> -->
            <sphere radius="0.025"/>
        </geometry>
        </collision>
        <inertial>
        <mass value="0.06"/>
        <!-- the same as a1 -->
        <inertia ixx="9.6e-06" ixy="0.0" ixz="0.0" iyy="9.6e-06" iyz="0.0" izz="9.6e-06"/>
        </inertial>
    </link>
    <joint name="RR_hip_joint" type="revolute">
        <origin rpy="0 0 0" xyz="-0.1995 -0.05001 0"/>
        <parent link="trunk"/>
        <child link="RR_hip"/>
        <axis xyz="1 0 0"/>
        <dynamics damping="0" friction="0"/>
        <!-- <limit effort="20" lower="-0.802851455917" upper="0.802851455917" velocity="52.4"/> -->
        <limit effort="18" lower="-0.94" upper="0.94" velocity="40"/>
    </joint>
    <link name="RR_hip">
        <visual>
        <!-- <origin rpy="3.14159265359 3.14159265359 0" xyz="0 0 0"/> -->
        <origin rpy="0 0 0" xyz="0 0 0"/>
        <geometry>
            <mesh filename="package://sz_description/meshes/RR_hip.dae" scale="1 1 1"/>
        </geometry>
        <material name="silver"/>
        </visual>
        <!-- <collision>
        <origin rpy="1.57079632679 0 0" xyz="0 0 0"/>
        <geometry>
            <cylinder length="0.04" radius="0.046"/>
        </geometry>
        </collision> -->
        <inertial>
        <origin rpy="0 0 0" xyz="-0.0037743 0.0038894 7.8535E-05"/>
        <mass value="0.68"/>
        <inertia ixx="0.000469246" ixy="9.409e-06" ixz="-3.42e-07" iyy="0.00080749" iyz="4.66e-07" izz="0.000552929"/>
        <!-- <inertia ixx="4.602822857142857e-4" ixy="-9.953142857142857e-6" ixz="3.394285714285714e-7" iyy="7.898548571428571e-4" iyz="6.228571428571429e-7" izz="5.576217142857143e-4" /> -->
        </inertial>
    </link>
    <joint name="RR_hip_fixed" type="fixed">
        <origin rpy="0 0 0" xyz="0 -0.081 0"/>
        <parent link="RR_hip"/>
        <child link="RR_thigh_shoulder"/>
    </joint>
    <!-- this link is only for collision -->
    <link name="RR_thigh_shoulder">
        <!-- <collision>
        <origin rpy="1.57079632679 0 0" xyz="0 0 0"/>
        <geometry>
            <cylinder length="0.032" radius="0.041"/>
        </geometry>
        </collision> -->
    </link>
    <joint name="RR_thigh_joint" type="revolute">
        <origin rpy="0 0 0" xyz="0 -0.08985 0"/>
        <parent link="RR_hip"/>
        <child link="RR_thigh"/>
        <axis xyz="0 1 0"/>
        <dynamics damping="0" friction="0"/>
        <!-- <limit effort="55" lower="-1.0471975512" upper="4.18879020479" velocity="28.6"/> -->
        <!-- <limit effort="18" lower="-1.46" upper="1.93" velocity="40"/> -->
        <limit effort="18" lower="-0.409203673" upper="3.550796326" velocity="40"/>
    </joint>
    <link name="RR_thigh">
        <visual>
        <origin rpy="0 0 0" xyz="0 0 0"/>
        <geometry>
            <mesh filename="package://sz_description/meshes/thigh.dae" scale="1 1 1"/>
        </geometry>
        <material name="silver"/>
        </visual>
        <!-- <collision>
        <origin rpy="0 1.57079632679 0" xyz="0 0 -0.1"/>
        <geometry>
            <box size="0.2 0.0245 0.034"/>
        </geometry>
        </collision> -->
        <collision>
        <origin xyz="0 0 -0.1" rpy="0 0 0" />
        <geometry>
            <box size="0.03 0.03 0.2"/>
        </geometry>
        </collision>
        <inertial>
        <origin rpy="0 0 0" xyz="-0.0025418 0.024397 -0.017202"/>
        <mass value="1.009"/>
        <inertia ixx="0.006118" ixy="0.0" ixz="0.0" iyy="0.006749" iyz="0.0" izz="0.001051"/>
        <!-- <inertia ixx="0.0059674237094595" ixy="2.463414414414414e-6" ixz="3.941565326576577e-4" iyy="0.0056818460304054" iyz="3.201302477477477e-5" izz="0.0012614772522523" /> -->
        </inertial>
    </link>
    <joint name="RR_calf_joint" type="revolute">
        <origin rpy="0 0 0" xyz="0 -0.0001 -0.2"/>
        <parent link="RR_thigh"/>
        <child link="RR_calf"/>
        <axis xyz="0 1 0"/>
        <dynamics damping="0" friction="0"/>
        <!-- <limit effort="55" lower="-2.69653369433" upper="-0.916297857297" velocity="28.6"/> -->
        <limit effort="27" lower="-2.6" upper="-0.885" velocity="26.6"/>
    </joint>
    <link name="RR_calf">
        <visual>
        <origin rpy="0 0 0" xyz="0 0 0"/>
        <geometry>
            <mesh filename="package://sz_description/meshes/calf.dae" scale="1 1 1"/>
        </geometry>
        <material name="silver"/>
        </visual>
        <!-- <collision>
        <origin rpy="0 1.57079632679 0" xyz="0 0 -0.1"/>
        <geometry>
            <box size="0.2 0.016 0.016"/>
        </geometry>
        </collision> -->
        <collision>
        <origin xyz="0 0 -0.1" rpy="0 0 0" />
        <geometry>
            <box size="0.02 0.02 0.2"/>
        </geometry>
        </collision>
        <inertial>
        <origin rpy="0 0 0" xyz="0.0052583 4.9987E-08 -0.11963"/>
        <mass value="0.224"/>
        <inertia ixx="0.001269" ixy="0.0" ixz="0.0" iyy="0.001277" iyz="0.0" izz="0.00002425"/>
        <!-- <inertia ixx="0.0034783165033113" ixy="0.0" ixz="-2.095735099337748e-4" iyy="0.0035020471523179" iyz="0.0" izz="4.622113907284768e-5" /> -->
        </inertial>
    </link>
    <joint name="RR_foot_fixed" type="fixed" dont_collapse="true">
        <origin rpy="0 0 0" xyz="0 0 -0.2"/>
        <parent link="RR_calf"/>
        <child link="RR_foot"/>
    </joint>
    <link name="RR_foot">
        <visual>
        <origin rpy="0 0 0" xyz="0 0 0"/>
        <geometry>
            <sphere radius="0.01"/>
        </geometry>
        <material name="silver"/>
        </visual>
        <collision>
        <origin rpy="0 0 0" xyz="0 0 0"/>
        <geometry>
            <!-- <sphere radius="0.02"/> -->
            <sphere radius="0.025"/>
        </geometry>
        </collision>
        <inertial>
        <mass value="0.06"/>
        <!-- the same as a1 -->
        <inertia ixx="9.6e-06" ixy="0.0" ixz="0.0" iyy="9.6e-06" iyz="0.0" izz="9.6e-06"/>
        </inertial>
    </link>
    <joint name="RL_hip_joint" type="revolute">
        <origin rpy="0 0 0" xyz="-0.1995 0.04999 0"/>
        <parent link="trunk"/>
        <child link="RL_hip"/>
        <axis xyz="1 0 0"/>
        <dynamics damping="0" friction="0"/>
        <!-- <limit effort="20" lower="-0.802851455917" upper="0.802851455917" velocity="52.4"/> -->
        <limit effort="18" lower="-0.94" upper="0.94" velocity="40"/>
    </joint>
    <link name="RL_hip">
        <visual>
        <!-- <origin rpy="0 3.14159265359 0" xyz="0 0 0"/> -->
        <origin xyz="0 0 0" rpy="0 0 0" />
        <geometry>
            <mesh filename="package://sz_description/meshes/RL_hip.dae" scale="1 1 1"/>
        </geometry>
        <material name="silver"/>
        </visual>
        <!-- <collision>
        <origin rpy="1.57079632679 0 0" xyz="0 0 0"/>
        <geometry>
            <cylinder length="0.04" radius="0.046"/>
        </geometry>
        </collision> -->
        <inertial>
        <origin rpy="0 0 0" xyz="-0.0037743 -0.0038894 7.8535E-05"/>
        <mass value="0.68"/>
        <inertia ixx="0.000469246" ixy="9.409e-06" ixz="-3.42e-07" iyy="0.00080749" iyz="4.66e-07" izz="0.000552929"/>
        <!-- <inertia ixx="4.602822857142857e-4" ixy="9.953142857142857e-6" ixz="3.394285714285714e-7" iyy="7.898548571428571e-4" iyz="-6.228571428571429e-7" izz="5.576217142857143e-4" /> -->
        </inertial>
    </link>
    <joint name="RL_hip_fixed" type="fixed">
        <origin rpy="0 0 0" xyz="0 0.081 0"/>
        <parent link="RL_hip"/>
        <child link="RL_thigh_shoulder"/>
    </joint>
    <!-- this link is only for collision -->
    <link name="RL_thigh_shoulder">
        <!-- <collision>
        <origin rpy="1.57079632679 0 0" xyz="0 0 0"/>
        <geometry>
            <cylinder length="0.032" radius="0.041"/>
        </geometry>
        </collision> -->
    </link>
    <joint name="RL_thigh_joint" type="revolute">
        <origin rpy="0 0 0" xyz="0 0.08985 0"/>
        <parent link="RL_hip"/>
        <child link="RL_thigh"/>
        <axis xyz="0 1 0"/>
        <dynamics damping="0" friction="0"/>
        <!-- <limit effort="55" lower="-1.0471975512" upper="4.18879020479" velocity="28.6"/> -->
        <!-- <limit effort="18" lower="-1.46" upper="1.93" velocity="40"/> -->
        <limit effort="18" lower="-0.409203673" upper="3.550796326" velocity="40"/>
    </joint>
    <link name="RL_thigh">
        <visual>
        <origin rpy="0 0 0" xyz="0 0 0"/>
        <geometry>
            <mesh filename="package://sz_description/meshes/thigh_mirror.dae" scale="1 1 1"/>
        </geometry>
        <material name="silver"/>
        </visual>
        <!-- <collision>
        <origin rpy="0 1.57079632679 0" xyz="0 0 -0.1"/>
        <geometry>
            <box size="0.2 0.0245 0.034"/>
        </geometry>
        </collision> -->
        <collision>
        <origin xyz="0 0 -0.1" rpy="0 0 0" />
        <geometry>
            <box size="0.03 0.03 0.2"/>
        </geometry>
        </collision>
        <inertial>
        <origin rpy="0 0 0" xyz="-0.002926 -0.024388 -0.017656"/>
        <mass value="1.009"/>
        <inertia ixx="0.006118" ixy="0.0" ixz="0.0" iyy="0.006749" iyz="0.0" izz="0.001051"/>
        <!-- <inertia ixx="0.0059674237094595" ixy="-2.463414414414414e-6" ixz="3.941565326576577e-4" iyy="0.0056818460304054" iyz="-3.201302477477477e-5" izz="0.0012614772522523" /> -->
        </inertial>
    </link>
    <joint name="RL_calf_joint" type="revolute">
        <origin rpy="0 0 0" xyz="0 0.0001 -0.2"/>
        <parent link="RL_thigh"/>
        <child link="RL_calf"/>
        <axis xyz="0 1 0"/>
        <dynamics damping="0" friction="0"/>
        <!-- <limit effort="55" lower="-2.69653369433" upper="-0.916297857297" velocity="28.6"/> -->
        <limit effort="27" lower="-2.6" upper="-0.885" velocity="26.6"/>
    </joint>
    <link name="RL_calf">
        <visual>
        <origin rpy="0 0 0" xyz="0 0 0"/>
        <geometry>
            <mesh filename="package://sz_description/meshes/calf.dae" scale="1 1 1"/>
        </geometry>
        <material name="silver"/>
        </visual>
        <!-- <collision>
        <origin rpy="0 1.57079632679 0" xyz="0 0 -0.1"/>
        <geometry>
            <box size="0.2 0.016 0.016"/>
        </geometry>
        </collision> -->
        <collision>
        <origin xyz="0 0 -0.1" rpy="0 0 0" />
        <geometry>
            <box size="0.02 0.02 0.2"/>
        </geometry>
        </collision>
        <inertial>
        <origin rpy="0 0 0" xyz="0.0052583 3.799E-08 -0.11963"/>
        <mass value="0.224"/>
        <inertia ixx="0.001269" ixy="0.0" ixz="0.0" iyy="0.001277" iyz="0.0" izz="0.00002425"/>
        <!-- <inertia ixx="0.0034783165033113" ixy="0.0" ixz="-1.614571428571429e-4" iyy="0.0026824344538288" iyz="0.0" izz="3.540362837837838e-5" /> -->
        </inertial>
    </link>
    <joint name="RL_foot_fixed" type="fixed" dont_collapse="true">
        <origin rpy="0 0 0" xyz="0 0 -0.2"/>
        <parent link="RL_calf"/>
        <child link="RL_foot"/>
    </joint>
    <link name="RL_foot">
        <visual>
        <origin rpy="0 0 0" xyz="0 0 0"/>
        <geometry>
            <sphere radius="0.01"/>
        </geometry>
        <material name="silver"/>
        </visual>
        <collision>
        <origin rpy="0 0 0" xyz="0 0 0"/>
        <geometry>
            <sphere radius="0.025"/>
        </geometry>
        </collision>
        <inertial>
        <mass value="0.06"/>
        <!-- the same as a1 -->
        <inertia ixx="9.6e-06" ixy="0.0" ixz="0.0" iyy="9.6e-06" iyz="0.0" izz="9.6e-06"/>
        </inertial>
    </link>
    <!-- <xacro:leg name="FR" mirror="-1" mirror_dae= "False" front_hind="1" front_hind_dae="True" />
    <xacro:leg name="FL" mirror="1" mirror_dae="True" front_hind="1" front_hind_dae="True" />
    <xacro:leg name="RR" mirror="-1" mirror_dae="False" front_hind="-1" front_hind_dae="False" />
    <xacro:leg name="RL" mirror="1" mirror_dae="True" front_hind="-1" front_hind_dae="False" /> -->

    <xacro:leg_transmission name="FR" />
    <xacro:leg_transmission name="FL" />
    <xacro:leg_transmission name="RR" />
    <xacro:leg_transmission name="RL" />


</robot>