<?xml version="1.0" encoding="utf-8"?>
<!-- This URDF was automatically created by SolidWorks to URDF Exporter! Originally created by Stephen Brawner (brawner@gmail.com) 
     Commit Version: 1.5.1-0-g916b5db  Build Version: 1.5.7152.31018
     For more information, please see http://wiki.ros.org/sw_urdf_exporter -->
<robot
  name="xb4_description">
  <link
    name="base_link">
    <inertial>
      <origin
        xyz="-0.0245 1.2081E-05 0.087704"
        rpy="0 0 0" />
      <mass
        value="52.11" />
      <inertia
        ixx="0.24895"
        ixy="0.00013269"
        ixz="-0.0050593"
        iyy="0.3729"
        iyz="-3.2127E-05"
        izz="0.34855" />
    </inertial>
    <visual>
      <origin
        xyz="0 0 0"
        rpy="0 0 0" />
      <geometry>
        <mesh
          filename="package://xb4_description/meshes/base_link.STL" />
      </geometry>
      <material
        name="">
        <color
          rgba="0.75294 0.75294 0.75294 1" />
      </material>
    </visual>
    <collision>
      <origin
        xyz="0 0 0"
        rpy="0 0 0" />
      <geometry>
        <mesh
          filename="package://xb4_description/meshes/base_link.STL" />
      </geometry>
    </collision>
  </link>
  <link
    name="Link1">
    <inertial>
      <origin
        xyz="0.011449 0.00070297 0.079628"
        rpy="0 0 0" />
      <mass
        value="28.663" />
      <inertia
        ixx="0.209"
        ixy="-0.00046488"
        ixz="-0.026126"
        iyy="0.15579"
        iyz="-0.0012509"
        izz="0.15718" />
    </inertial>
    <visual>
      <origin
        xyz="0 0 0"
        rpy="0 0 0" />
      <geometry>
        <mesh
          filename="package://xb4_description/meshes/Link1.STL" />
      </geometry>
      <material
        name="">
        <color
          rgba="0.75294 0.75294 0.75294 1" />
      </material>
    </visual>
    <collision>
      <origin
        xyz="0 0 0"
        rpy="0 0 0" />
      <geometry>
        <mesh
          filename="package://xb4_description/meshes/Link1.STL" />
      </geometry>
    </collision>
  </link>
  <joint
    name="Joint1"
    type="revolute">
    <origin
      xyz="0.00098343 0 0.184"
      rpy="0 0 0" />
    <parent
      link="base_link" />
    <child
      link="Link1" />
    <axis
      xyz="0 0 1" />
    <limit
      lower="-3.14"
      upper="3.14"
      effort="20"
      velocity="40" />
  </joint>
  <link
    name="Link2">
    <inertial>
      <origin
        xyz="-0.010007 0.049583 0.11809"
        rpy="0 0 0" />
      <mass
        value="31.841" />
      <inertia
        ixx="0.38868"
        ixy="7.3853E-05"
        ixz="0.0047598"
        iyy="0.32881"
        iyz="-0.0043661"
        izz="0.1148" />
    </inertial>
    <visual>
      <origin
        xyz="0 0 0"
        rpy="0 0 0" />
      <geometry>
        <mesh
          filename="package://xb4_description/meshes/Link2.STL" />
      </geometry>
      <material
        name="">
        <color
          rgba="0.75294 0.75294 0.75294 1" />
      </material>
    </visual>
    <collision>
      <origin
        xyz="0 0 0"
        rpy="0 0 0" />
      <geometry>
        <mesh
          filename="package://xb4_description/meshes/Link2.STL" />
      </geometry>
    </collision>
  </link>
  <joint
    name="Joint2"
    type="revolute">
    <origin
      xyz="0.040007 -0.0495 0.155"
      rpy="0 0 0" />
    <parent
      link="Link1" />
    <child
      link="Link2" />
    <axis
      xyz="0 1 0" />
    <limit
      lower="-3.14"
      upper="3.14"
      effort="20"
      velocity="40" />
  </joint>
  <link
    name="Link3">
    <inertial>
      <origin
        xyz="0.0067255 0.056241 0.010623"
        rpy="0 0 0" />
      <mass
        value="15.368" />
      <inertia
        ixx="0.032143"
        ixy="-0.00018372"
        ixz="-0.0049172"
        iyy="0.048616"
        iyz="-5.9262E-05"
        izz="0.044126" />
    </inertial>
    <visual>
      <origin
        xyz="0 0 0"
        rpy="0 0 0" />
      <geometry>
        <mesh
          filename="package://xb4_description/meshes/Link3.STL" />
      </geometry>
      <material
        name="">
        <color
          rgba="0.75294 0.75294 0.75294 1" />
      </material>
    </visual>
    <collision>
      <origin
        xyz="0 0 0"
        rpy="0 0 0" />
      <geometry>
        <mesh
          filename="package://xb4_description/meshes/Link3.STL" />
      </geometry>
    </collision>
  </link>
  <joint
    name="Joint3"
    type="revolute">
    <origin
      xyz="0 -0.008 0.275"
      rpy="0 0 0" />
    <parent
      link="Link2" />
    <child
      link="Link3" />
    <axis
      xyz="0 1 0" />
    <limit
      lower="-3.14"
      upper="3.14"
      effort="20"
      velocity="40" />
  </joint>
  <link
    name="Link4">
    <inertial>
      <origin
        xyz="0.080048 0.00019844 0.00018069"
        rpy="0 0 0" />
      <mass
        value="13.118" />
      <inertia
        ixx="0.023976"
        ixy="-0.0005894"
        ixz="0.00011166"
        iyy="0.049908"
        iyz="5.1715E-06"
        izz="0.055207" />
    </inertial>
    <visual>
      <origin
        xyz="0 0 0"
        rpy="0 0 0" />
      <geometry>
        <mesh
          filename="package://xb4_description/meshes/Link4.STL" />
      </geometry>
      <material
        name="">
        <color
          rgba="0.75294 0.75294 0.75294 1" />
      </material>
    </visual>
    <collision>
      <origin
        xyz="0 0 0"
        rpy="0 0 0" />
      <geometry>
        <mesh
          filename="package://xb4_description/meshes/Link4.STL" />
      </geometry>
    </collision>
  </link>
  <joint
    name="Joint4"
    type="revolute">
    <origin
      xyz="0.09718 0.0575 0.024999"
      rpy="0 0 0" />
    <parent
      link="Link3" />
    <child
      link="Link4" />
    <axis
      xyz="1 0 0" />
    <limit
      lower="-3.14"
      upper="3.14"
      effort="20"
      velocity="40" />
  </joint>
  <link
    name="Link5">
    <inertial>
      <origin
        xyz="0.014859 -0.033648 7.8205E-05"
        rpy="0 0 0" />
      <mass
        value="3.0282" />
      <inertia
        ixx="0.0019642"
        ixy="-4.6957E-05"
        ixz="-3.4436E-06"
        iyy="0.0034401"
        iyz="-1.1677E-07"
        izz="0.0033234" />
    </inertial>
    <visual>
      <origin
        xyz="0 0 0"
        rpy="0 0 0" />
      <geometry>
        <mesh
          filename="package://xb4_description/meshes/Link5.STL" />
      </geometry>
      <material
        name="">
        <color
          rgba="0.75294 0.75294 0.75294 1" />
      </material>
    </visual>
    <collision>
      <origin
        xyz="0 0 0"
        rpy="0 0 0" />
      <geometry>
        <mesh
          filename="package://xb4_description/meshes/Link5.STL" />
      </geometry>
    </collision>
  </link>
  <joint
    name="Joint5"
    type="revolute">
    <origin
      xyz="0.18282 0.0325 0"
      rpy="0 0 0" />
    <parent
      link="Link4" />
    <child
      link="Link5" />
    <axis
      xyz="0 1 0" />
    <limit
      lower="-3.14"
      upper="3.14"
      effort="20"
      velocity="40" />
  </joint>
  <link
    name="Link6">
    <inertial>
      <origin
        xyz="0.0045911 5.7515E-08 -0.0002189"
        rpy="0 0 0" />
      <mass
        value="0.077253" />
      <inertia
        ixx="1.734E-05"
        ixy="2.7594E-20"
        ixz="3.2231E-08"
        iyy="9.1859E-06"
        iyz="2.296E-19"
        izz="9.4556E-06" />
    </inertial>
    <visual>
      <origin
        xyz="0 0 0"
        rpy="0 0 0" />
      <geometry>
        <mesh
          filename="package://xb4_description/meshes/Link6.STL" />
      </geometry>
      <material
        name="">
        <color
          rgba="0.75294 0.75294 0.75294 1" />
      </material>
    </visual>
    <collision>
      <origin
        xyz="0 0 0"
        rpy="0 0 0" />
      <geometry>
        <mesh
          filename="package://xb4_description/meshes/Link6.STL" />
      </geometry>
    </collision>
  </link>
  <joint
    name="Joint6"
    type="revolute">
    <origin
      xyz="0.063 -0.0325 0"
      rpy="0 0 0" />
    <parent
      link="Link5" />
    <child
      link="Link6" />
    <axis
      xyz="1 0 0" />
    <limit
      lower="-3.14"
      upper="3.14"
      effort="20"
      velocity="40" />
  </joint>
</robot>