<?xml version="1.0"?>

<robot xmlns:xacro="http://www.ros.org/wiki/xacro">
  <xacro:macro name="qa01_description" params="debug">

    <link name="world" />
    <joint name="world_fixed" type="fixed">
      <parent link="world" />
      <child link="base_link" />
    </joint>

  <link
    name="base_link">
    <inertial>
      <origin
        xyz="0.00039738 -0.00005889 0.06018277"
        rpy="0 0 0" />
      <mass
        value="1.235" />
      <inertia
        ixx="0.00151953"
        ixy="0.00000173"
        ixz="-0.00001964"
        iyy="0.00146074"
        iyz="0.00000259"
        izz="0.00110167" />
    </inertial>
    <visual>
      <origin
        xyz="0 0 0"
        rpy="0 0 0" />
      <geometry>
        <mesh
          filename="/home/wl/Documents/simulation_all_ros2/src/robot_description/qa01/meshes/base_link.STL" />
      </geometry>
      <material
        name="">
        <color
          rgba="1 1 1 1" />
      </material>
    </visual>
    <collision>
      <origin
        xyz="0 0 0"
        rpy="0 0 0" />
      <geometry>
        <mesh
          filename="/home/wl/Documents/simulation_all_ros2/src/robot_description/qa01/meshes/base_link.STL" />
      </geometry>
    </collision>
  </link>

  <joint
    name="Joint1"
    type="revolute">
    <origin
      xyz="0 0 0.107"
      rpy="0 0 0" />
    <parent
      link="base_link" />
    <child
      link="Link1" />
    <axis
      xyz="0 0 1" />
    <limit
      lower="-2.2"
      upper="3.0"
      effort="20"
      velocity="1.57" />
  </joint>

  <link
    name="Link1">
    <inertial>
      <origin
        xyz="0.00002637 0.03034462 0.02957486"
        rpy="0 0 0" />
      <mass
        value="0.256" />
      <inertia
        ixx="0.00034307"
        ixy="-0.00000043"
        ixz="-0.00000019"
        iyy="0.00031904"
        iyz="0.00009123"
        izz="0.00031265" />
    </inertial>
    <visual>
      <origin
        xyz="0 0 0"
        rpy="0 0 0" />
      <geometry>
        <mesh
          filename="/home/wl/Documents/simulation_all_ros2/src/robot_description/qa01/meshes/Link1.STL" />
      </geometry>
      <material
        name="">
        <color
          rgba="1 1 1 1" />
      </material>
    </visual>
    <collision>
      <origin
        xyz="0 0 0"
        rpy="0 0 0" />
      <geometry>
        <mesh
          filename="/home/wl/Documents/simulation_all_ros2/src/robot_description/qa01/meshes/Link1.STL" />
      </geometry>
    </collision>
  </link>

  <joint
    name="Joint2"
    type="revolute">
    <origin
      xyz="0 0.041 0.058"
      rpy="0 0 0" />
    <parent
      link="Link1" />
    <child
      link="Link2" />
    <axis
      xyz="0 1 0" />
    <limit
      lower="0"
      upper="3.0"
      effort="20"
      velocity="1.57" />
  </joint>

  <link
    name="Link2">
    <inertial>
      <origin
        xyz="-0.18055472 -0.04510178 0.00003829"
        rpy="0 0 0" />
      <mass
        value="2.968" />
      <inertia
        ixx="0.00266709"
        ixy="0.00180103"
        ixz="0.00003559"
        iyy="0.1109826"
        iyz="0.0000056"
        izz="0.11142386" />
    </inertial>
    <visual>
      <origin
        xyz="0 0 0"
        rpy="0 0 0" />
      <geometry>
        <mesh
          filename="/home/wl/Documents/simulation_all_ros2/src/robot_description/qa01/meshes/Link2.STL" />
      </geometry>
      <material
        name="">
        <color
          rgba="1 1 1 1" />
      </material>
    </visual>
    <collision>
      <origin
        xyz="0 0 0"
        rpy="0 0 0" />
      <geometry>
        <mesh
          filename="/home/wl/Documents/simulation_all_ros2/src/robot_description/qa01/meshes/Link2.STL" />
      </geometry>
    </collision>
  </link>

  <joint
    name="Joint3"
    type="revolute">
    <origin
      xyz="-0.41 -0.0095 0"
      rpy="0 0 0" />
    <parent
      link="Link2" />
    <child
      link="Link3" />
    <axis
      xyz="0 1 0" />
    <limit
      lower="-3.0"
      upper="0"
      effort="20"
      velocity="1.57" />
  </joint>
  
  <link
    name="Link3">
    <inertial>
      <origin
        xyz="0.08202737 -0.02788467 0.07516671"
        rpy="0 0 0" />
      <mass
        value="1.356" />
      <inertia
        ixx="0.00204921"
        ixy="-0.00040930"
        ixz="0.00107577"
        iyy="0.00395056"
        iyz="-0.00037046"
        izz="0.00335315" />
    </inertial>
    <visual>
      <origin
        xyz="0 0 0"
        rpy="0 0 0" />
      <geometry>
        <mesh
          filename="/home/wl/Documents/simulation_all_ros2/src/robot_description/qa01/meshes/Link3.STL" />
      </geometry>
      <material
        name="">
        <color
          rgba="1 1 1 1" />
      </material>
    </visual>
    <collision>
      <origin
        xyz="0 0 0"
        rpy="0 0 0" />
      <geometry>
        <mesh
          filename="/home/wl/Documents/simulation_all_ros2/src/robot_description/qa01/meshes/Link3.STL" />
      </geometry>
    </collision>
  </link>

  <joint
    name="Joint4"
    type="revolute">
    <origin
      xyz="0.1415 -0.0315 0.085"
      rpy="0 0 0" />
    <parent
      link="Link3" />
    <child
      link="Link4" />
    <axis
      xyz="1 0 0" />
    <limit
      lower="-2.2"
      upper="3.0"
      effort="20"
      velocity="1.57" />
  </joint>

  <link
    name="Link4">
    <inertial>
      <origin
        xyz="0.20592565 -0.00384981 0.00001806"
        rpy="0 0 0" />
      <mass
        value="1.462" />
      <inertia
        ixx="0.0011947"
        ixy="-0.00025098"
        ixz="0.00000122"
        iyy="0.01082010"
        iyz="-0.00000088"
        izz="0.01098098" />
    </inertial>
    <visual>
      <origin
        xyz="0 0 0"
        rpy="0 0 0" />
      <geometry>
        <mesh
          filename="/home/wl/Documents/simulation_all_ros2/src/robot_description/qa01/meshes/Link4.STL" />
      </geometry>
      <material
        name="">
        <color
          rgba="1 1 1 1" />
      </material>
    </visual>
    <collision>
      <origin
        xyz="0 0 0"
        rpy="0 0 0" />
      <geometry>
        <mesh
          filename="/home/wl/Documents/simulation_all_ros2/src/robot_description/qa01/meshes/Link4.STL" />
      </geometry>
    </collision>
  </link>

  <joint
    name="Joint5"
    type="revolute">
    <origin
      xyz="0.2495 0.0355 0"
      rpy="0 0 0" />
    <parent
      link="Link4" />
    <child
      link="Link5" />
    <axis
      xyz="0 1 0" />
    <limit
      lower="-1.55"
      upper="1.55"
      effort="20"
      velocity="1.57" />
  </joint>
  
  <link
    name="Link5">
    <inertial>
      <origin
        xyz="0.08093796 -0.03060322 -0.00005070"
        rpy="0 0 0" />
      <mass
        value="1.245" />
      <inertia
        ixx="0.00113585"
        ixy="-0.00043658"
        ixz="0.00000344"
        iyy="0.00195759"
        iyz="-0.00000175"
        izz="0.00212406" />
    </inertial>
    <visual>
      <origin
        xyz="0 0 0"
        rpy="0 0 0" />
      <geometry>
        <mesh
          filename="/home/wl/Documents/simulation_all_ros2/src/robot_description/qa01/meshes/Link5.STL" />
      </geometry>
      <material
        name="">
        <color
          rgba="1 1 1 1" />
      </material>
    </visual>
    <collision>
      <origin
        xyz="0 0 0"
        rpy="0 0 0" />
      <geometry>
        <mesh
          filename="/home/wl/Documents/simulation_all_ros2/src/robot_description/qa01/meshes/Link5.STL" />
      </geometry>
    </collision>
  </link>

  <joint
    name="Joint6"
    type="revolute">
    <origin
      xyz="0.1315 -0.0355 0"
      rpy="0 0 0" />
    <parent
      link="Link5" />
    <child
      link="Link6" />
    <axis
      xyz="1 0 0" />
    <limit
      lower="-2.2"
      upper="3.0"
      effort="20"
      velocity="1.57" />
  </joint>

  <link
    name="Link6">
    <inertial>
      <origin
        xyz="0.02024823 0.00000565 -0.00029493"
        rpy="0 0 0" />
      <mass
        value="0.301" />
      <inertia
        ixx="0.00027430"
        ixy="-0.00000002"
        ixz="-0.00000022"
        iyy="0.00019299"
        iyz="0.00000002"
        izz="0.00020068" />
    </inertial>
    <visual>
      <origin
        xyz="0 0 0"
        rpy="0 0 0" />
      <geometry>
        <mesh
          filename="/home/wl/Documents/simulation_all_ros2/src/robot_description/qa01/meshes/Link6.STL" />
      </geometry>
      <material
        name="">
        <color
          rgba="1 1 1 1" />
      </material>
    </visual>
    <collision>
      <origin
        xyz="0 0 0"
        rpy="0 0 0" />
      <geometry>
        <mesh
          filename="/home/wl/Documents/simulation_all_ros2/src/robot_description/qa01/meshes/Link6.STL" />
      </geometry>
    </collision>
  </link>

  <joint
    name="Joint7"
    type="fixed">
    <origin
      xyz="0.044 0 0"
      rpy="0 0 0" />
    <parent
      link="Link6" />
    <child
      link="Link7" />
  </joint>

  <link
    name="Link7">
    <inertial>
      <origin
        xyz="0.0575 0.0008 -0.0097"
        rpy="0 0 0" />
      <mass
        value="0.304" />
      <inertia
        ixx="0.00020389"
        ixy="-0.00000088"
        ixz="-0.00012161"
        iyy="0.00075402"
        iyz="0.00000391"
        izz="0.00074432" />
    </inertial>
    <visual>
      <origin
        xyz="0 0 0"
        rpy="0 0 0" />
      <geometry>
        <mesh
          filename="/home/wl/Documents/simulation_all_ros2/src/robot_description/qa01/meshes/Link7.STL" />
      </geometry>
      <material
        name="">
        <color
          rgba="1 1 1 1" />
      </material>
    </visual>
    <collision>
      <origin
        xyz="0 0 0"
        rpy="0 0 0" />
      <geometry>
        <mesh
          filename="/home/wl/Documents/simulation_all_ros2/src/robot_description/qa01/meshes/Link7.STL" />
      </geometry>
    </collision>
  </link>

  <joint
    name="GripperUpJoint"
    type="revolute">
    <origin
      xyz="0.057 0.0002 0.022"
      rpy="0 0 0" />
    <parent
      link="Link7" />
    <child
      link="Link8" />
    <axis
      xyz="0 1 0" />
    <limit
      lower="-1.57"
      upper="0"
      effort="20"
      velocity="1.57" />
  </joint>

  <link
    name="Link8">
    <inertial>
      <origin
        xyz="0.0537 -0.0004 0.0075"
        rpy="0 0 0" />
      <mass
        value="0.134" />
      <inertia
        ixx="0.00009441"
        ixy="-0.00000004"
        ixz="-0.00004142"
        iyy="0.0002519"
        iyz="0.00000003"
        izz="0.00028101" />
    </inertial>
    <visual>
      <origin
        xyz="0 0 0"
        rpy="0 0 0" />
      <geometry>
        <mesh
          filename="/home/wl/Documents/simulation_all_ros2/src/robot_description/qa01/meshes/Link8.STL" />
      </geometry>
      <material
        name="">
        <color
          rgba="0.79608 0.82353 0.93725 1" />
      </material>
    </visual>
    <collision>
      <origin
        xyz="0 0 0"
        rpy="0 0 0" />
      <geometry>
        <mesh
          filename="/home/wl/Documents/simulation_all_ros2/src/robot_description/qa01/meshes/Link8.STL" />
      </geometry>
    </collision>
  </link>

  <joint
    name="FingerTipJoint"
    type="fixed">
    <origin
      xyz="0.046751 0 -0.002"
      rpy="0 0 0" />
    <parent
      link="Link8" />
    <child
      link="FingerTip" />
    <axis
      xyz="0 0 0" />
  </joint>

  <link
    name="FingerTip">
    <inertial>
      <origin
        xyz="0.020217 -1.2367E-08 -0.0028442"
        rpy="0 0 0" />
      <mass
        value="0.023" />
      <inertia
        ixx="0.00000717"
        ixy="0.0"
        ixz="0.00000344"
        iyy="0.00001425"
        iyz="0.0"
        izz="0.00001900" />
    </inertial>
    <visual>
      <origin
        xyz="0 0 0"
        rpy="0 0 0" />
      <geometry>
        <mesh
          filename="/home/wl/Documents/simulation_all_ros2/src/robot_description/qa01/meshes/FingerTip.STL" />
      </geometry>
      <material
        name="">
        <color
          rgba="0.29804 0.29804 0.29804 1" />
      </material>
    </visual>
    <collision>
      <origin
        xyz="0 0 0"
        rpy="0 0 0" />
      <geometry>
        <mesh
          filename="/home/wl/Documents/simulation_all_ros2/src/robot_description/qa01/meshes/FingerTip.STL" />
      </geometry>
    </collision>
  </link>

  <joint
    name="HandTipJoint"
    type="fixed">
    <origin
      xyz="0.10375 0.00020001 -0.013"
      rpy="0 0 0" />
    <parent
      link="Link7" />
    <child
      link="HandTip" />
    <axis
      xyz="0 0 0" />
  </joint>

  <link
    name="HandTip">
    <inertial>
      <origin
        xyz="0.015597 -0.00020003 -0.002"
        rpy="0 0 0" />
      <mass
        value="0.0207" />
      <inertia
        ixx="0.00000567"
        ixy="0.0"
        ixz="0.0"
        iyy="0.0000091"
        iyz="0.0"
        izz="0.00001493" />
    </inertial>
    <visual>
      <origin
        xyz="0 0 0"
        rpy="0 0 0" />
      <geometry>
        <mesh
          filename="/home/wl/Documents/simulation_all_ros2/src/robot_description/qa01/meshes/HandTip.STL" />
      </geometry>
      <material
        name="">
        <color
          rgba="0.29804 0.29804 0.29804 1" />
      </material>
    </visual>
    <collision>
      <origin
        xyz="0 0 0"
        rpy="0 0 0" />
      <geometry>
        <mesh
          filename="/home/wl/Documents/simulation_all_ros2/src/robot_description/qa01/meshes/HandTip.STL" />
      </geometry>
    </collision>
  </link>

  </xacro:macro>
</robot>